Workbook
Name _: #N/A
Name __JJ1: [4]지입S3!#REF!
Name __JJ10: [5]자재단가!#REF!
Name __JJ100: #N/A
Name __JJ101: #N/A
Name __JJ102: #N/A
Name __JJ103: #N/A
Name __JJ104: #N/A
Name __JJ105: #N/A
Name __JJ106: #N/A
Name __JJ107: #N/A
Name __JJ108: #N/A
Name __JJ109: #N/A
Name __JJ11: [5]자재단가!#REF!
Name __JJ110: #N/A
Name __JJ111: #N/A
Name __JJ112: #N/A
Name __JJ113: [5]자재단가!#REF!
Name __JJ114: [5]자재단가!#REF!
Name __JJ115: [5]자재단가!#REF!
Name __JJ116: [5]자재단가!#REF!
Name __JJ117: [5]자재단가!#REF!
Name __JJ118: [5]자재단가!#REF!
Name __JJ119: [5]자재단가!#REF!
Name __JJ12: [5]자재단가!#REF!
Name __JJ120: [5]자재단가!#REF!
Name __JJ121: [5]자재단가!#REF!
Name __JJ122: [5]자재단가!#REF!
Name __JJ123: [5]자재단가!#REF!
Name __JJ124: [5]자재단가!#REF!
Name __JJ125: [5]자재단가!#REF!
Name __JJ126: [5]자재단가!#REF!
Name __JJ127: [5]자재단가!#REF!
Name __JJ128: [5]자재단가!#REF!
Name __JJ129: [5]자재단가!#REF!
Name __JJ13: [5]자재단가!#REF!
Name __JJ130: [5]자재단가!#REF!
Name __JJ131: [5]자재단가!#REF!
Name __JJ132: [5]자재단가!#REF!
Name __JJ133: [5]자재단가!#REF!
Name __JJ134: [5]자재단가!#REF!
Name __JJ135: [5]자재단가!#REF!
Name __JJ136: [5]자재단가!#REF!
Name __JJ137: [5]자재단가!#REF!
Name __JJ138: [5]자재단가!#REF!
Name __JJ139: [5]자재단가!#REF!
Name __JJ14: [5]자재단가!#REF!
Name __JJ140: [5]자재단가!#REF!
Name __JJ141: #N/A
Name __JJ142: #N/A
Name __JJ143: #N/A
Name __JJ144: #N/A
Name __JJ145: #N/A
Name __JJ146: #N/A
Name __JJ147: #N/A
Name __JJ148: #N/A
Name __JJ149: #N/A
Name __JJ15: [5]자재단가!#REF!
Name __JJ150: #N/A
Name __JJ151: #N/A

Sheet 총괄표
M2: [단위 : 백만원]
A3: 총괄표 | C3: 26년 | D3: 27년 | E3: 28년 | F3: 29년 | G3: 30년 | H3: 31년 | I3: 32년 | J3: 33년 | K3: 34년 | L3: 35년 | M3: 합계
A4: 수선유지비 | B4: 건물/구축물 | C4: ='26년'!$Y4 -> 4188 | D4: ='27년'!$Y4 -> 4250.82 | E4: ='28년'!$Y4 -> 4314.5823 | F4: ='29년'!$Y4 -> 4465.0467 | G4: ='30년'!$Y4 -> 4532.0224 | H4: ='31년'!$Y4 -> 4600.0027 | I4: ='32년'!$Y4 -> 4669.0027 | J4: ='33년'!$Y4 -> 4739.0378 | K4: ='34년'!Y4 -> 4810.1233 | L4: ='35년'!Y4 -> 4882.2752 | M4: =SUM(C4:L4) -> 45450.913
B5: 열원정기점검 | C5: ='26년'!$Y5 -> 27778 | D5: ='27년'!$Y5 -> 24868.567 | E5: ='28년'!$Y5 -> 28397.67 | F5: ='29년'!$Y5 -> 27126.644 | G5: ='30년'!$Y5 -> 23929.805 | H5: ='31년'!$Y5 -> 27692.36 | I5: ='32년'!$Y5 -> 25202.829 | J5: ='33년'!$Y5 -> 27981.359 | K5: ='34년'!Y5 -> 26340.013 | L5: ='35년'!Y5 -> 28620.527 | M5: =SUM(C5:L5) -> 267937.78
B6: 열원경상정비 | C6: ='26년'!$Y6 -> 42740 | D6: ='27년'!$Y6 -> 44031.816 | E6: ='28년'!$Y6 -> 46525.368 | F6: ='29년'!$Y6 -> 47223.248 | G6: ='30년'!$Y6 -> 47931.597 | H6: ='31년'!$Y6 -> 48650.571 | I6: ='32년'!$Y6 -> 49380.33 | J6: ='33년'!$Y6 -> 50121.035 | K6: ='34년'!Y6 -> 50872.85 | L6: ='35년'!Y6 -> 51635.943 | M6: =SUM(C6:L6) -> 479112.76
B7: 열원정기유지보수 | C7: ='26년'!$Y7 -> 10084 | D7: ='27년'!$Y7 -> 10962.615 | E7: ='28년'!$Y7 -> 11112.849 | F7: ='29년'!$Y7 -> 10505.577 | G7: ='30년'!$Y7 -> 10660.951 | H7: ='31년'!$Y7 -> 8532.1454 | I7: ='32년'!$Y7 -> 8660.1876 | J7: ='33년'!$Y7 -> 8790.1054 | K7: ='34년'!Y7 -> 8921.927 | L7: ='35년'!Y7 -> 9004.2849 | M7: =SUM(C7:L7) -> 97234.643
B8: 열원보완및개선 | C8: ='26년'!$Y8 -> 15268 | D8: ='27년'!$Y8 -> 13830.838 | E8: ='28년'!$Y8 -> 14558.38 | F8: ='29년'!$Y8 -> 14568.739 | G8: ='30년'!$Y8 -> 14210.99 | H8: ='31년'!$Y8 -> 14911.018 | I8: ='32년'!$Y8 -> 14710.292 | J8: ='33년'!$Y8 -> 15328.456 | K8: ='34년'!Y8 -> 16126.961 | L8: ='35년'!Y8 -> 15936.647 | M8: =SUM(C8:L8) -> 149450.32
B9: 비저장품(보수자재) | C9: ='26년'!$Y9 -> 1499 | D9: ='27년'!$Y9 -> 3900.645 | E9: ='28년'!$Y9 -> 4018.542 | F9: ='29년'!$Y9 -> 4155.0065 | G9: ='30년'!$Y9 -> 4318.8316 | H9: ='31년'!$Y9 -> 4383.614 | I9: ='32년'!$Y9 -> 4449.3683 | J9: ='33년'!$Y9 -> 4329.111 | K9: ='34년'!Y9 -> 4583.8504 | L9: ='35년'!Y9 -> 4652.6082 | M9: =SUM(C9:L9) -> 40290.577
B10: 소모품(자재공기구) | C10: ='26년'!$Y10 -> 198 | D10: ='27년'!$Y10 -> 435.435 | E10: ='28년'!$Y10 -> 448.59602 | F10: ='29년'!$Y10 -> 474.42951 | G10: ='30년'!$Y10 -> 481.54595 | H10: ='31년'!$Y10 -> 488.76914 | I10: ='32년'!$Y10 -> 496.10068 | J10: ='33년'!$Y10 -> 483.26532 | K10: ='34년'!Y10 -> 511.09532 | L10: ='35년'!Y10 -> 518.76175 | M10: =SUM(C10:L10) -> 4535.9987
B11: 계 | C11: ='26년'!$Y11 -> 101755 | D11: ='27년'!$Y11 -> 102280.74 | E11: ='28년'!$Y11 -> 109375.99 | F11: ='29년'!$Y11 -> 108518.69 | G11: ='30년'!$Y11 -> 106065.74 | H11: ='31년'!$Y11 -> 109258.48 | I11: ='32년'!$Y11 -> 107568.11 | J11: ='33년'!$Y11 -> 111772.37 | K11: ='34년'!$Y11 -> 112166.82 | L11: ='35년'!$Y11 -> 115251.05 | M11: =SUM(C11:L11) -> 1084013
A12: 지급수수료 | B12: 지급수수료 열원 | C12: ='26년'!$Y12 -> 5756 | D12: ='27년'!$Y12 -> 5659.8277 | E12: ='28년'!$Y12 -> 5744.7251 | F12: ='29년'!$Y12 -> 5944.8749 | G12: ='30년'!$Y12 -> 6034.048 | H12: ='31년'!$Y12 -> 6124.5588 | I12: ='32년'!$Y12 -> 6216.4272 | J12: ='33년'!$Y12 -> 6309.6736 | K12: ='34년'!Y12 -> 6404.3187 | L12: ='35년'!Y12 -> 6500.3834 | M12: =SUM(C12:L12) -> 60694.837
A13: 손익예산 합계 | C13: =C11+C12 -> 107511 | D13: =D11+D12 -> 107940.56 | E13: =E11+E12 -> 115120.71 | F13: =F11+F12 -> 114463.57 | G13: =G11+G12 -> 112099.79 | H13: =H11+H12 -> 115383.04 | I13: =I11+I12 -> 113784.54 | J13: =J11+J12 -> 118082.04 | ... L13: =L11+L12 -> 121751.43 | M13: =SUM(C13:L13) -> 1144707.8
A14: 건물 | C14: ='26년'!$Y14 -> 120 | D14: ='27년'!$Y14 -> 64 | E14: ='28년'!$Y14 -> 67 | F14: ='29년'!$Y14 -> 64 | G14: ='30년'!$Y14 -> 67 | H14: ='31년'!$Y14 -> 64 | I14: ='32년'!$Y14 -> 67 | J14: ='33년'!$Y14 -> 64 | K14: ='34년'!Y14 -> 67 | L14: ='35년'!Y14 -> 64 | M14: =SUM(C14:L14) -> 708
A15: 구축물 | C15: ='26년'!$Y15 -> 50 | D15: ='27년'!$Y15 -> 15 | E15: ='28년'!$Y15 -> 15 | F15: ='29년'!$Y15 -> 15 | G15: ='30년'!$Y15 -> 15 | H15: ='31년'!$Y15 -> 65 | I15: ='32년'!$Y15 -> 15 | J15: ='33년'!$Y15 -> 15 | K15: ='34년'!Y15 -> 15 | L15: ='35년'!Y15 -> 15 | M15: =SUM(C15:L15) -> 235
A16: 기계장치 | B16: 고온부품재생+LTSA | C16: ='26년'!$Y16 -> 16719 | D16: ='27년'!$Y16 -> 6120 | E16: ='28년'!$Y16 -> 16440.251 | F16: ='29년'!$Y16 -> 24522.969 | G16: ='30년'!$Y16 -> 11853 | H16: ='31년'!$Y16 -> 19145 | I16: ='32년'!$Y16 -> 12543.487 | J16: ='33년'!$Y16 -> 13440.364 | K16: ='34년'!Y16 -> 3489 | L16: ='35년'!Y16 -> 5282.6434 | M16: =SUM(C16:L16) -> 129555.71
B17: 기타기계장치 | C17: ='26년'!$Y17 -> 56441 | D17: ='27년'!$Y17 -> 19347.946 | E17: ='28년'!$Y17 -> 31407.071 | F17: ='29년'!$Y17 -> 14695.858 | G17: ='30년'!$Y17 -> 17909.211 | H17: ='31년'!$Y17 -> 17273.059 | I17: ='32년'!$Y17 -> 17266.099 | J17: ='33년'!$Y17 -> 15236.931 | K17: ='34년'!Y17 -> 18622.447 | L17: ='35년'!Y17 -> 16455.669 | M17: =SUM(C17:L17) -> 224655.29
B18: 계 | C18: =C16+C17 -> 73160 | D18: =D16+D17 -> 25467.946 | E18: =E16+E17 -> 47847.322 | F18: =F16+F17 -> 39218.827 | G18: =G16+G17 -> 29762.211 | H18: =H16+H17 -> 36418.059 | I18: =I16+I17 -> 29809.586 | J18: =J16+J17 -> 28677.295 | ... L18: =L16+L17 -> 21738.313 | M18: =SUM(C18:L18) -> 354211.01
A19: 건가-외주비 | B19: 중대형 MI 및 소형 A급 정비 | C19: ='26년'!$Y19 -> 2392 | D19: ='27년'!$Y19 -> 0 | E19: ='28년'!$Y19 -> 14761.168 | F19: ='29년'!$Y19 -> 5075 | G19: ='30년'!$Y19 -> 8711.6158 | H19: ='31년'!$Y19 -> 15108.122 | I19: ='32년'!$Y19 -> 3985.4531 | J19: ='33년'!$Y19 -> 0 | K19: ='34년'!Y19 -> 16140.5 | L19: ='35년'!Y19 -> 9716.7267 | M19: =SUM(C19:L19) -> 75890.585
A20: 공구와기구 | C20: ='26년'!$Y20 -> 1484 | D20: ='27년'!$Y20 -> 936.77608 | E20: ='28년'!$Y20 -> 1310.7905 | F20: ='29년'!$Y20 -> 1486.6942 | G20: ='30년'!$Y20 -> 1037.8349 | H20: ='31년'!$Y20 -> 1041.7793 | I20: ='32년'!$Y20 -> 1277.5263 | J20: ='33년'!$Y20 -> 1011.8224 | K20: ='34년'!Y20 -> 1165.7543 | L20: ='35년'!Y20 -> 1174.9306 | M20: =SUM(C20:L20) -> 11927.908
A21: 예비품 | B21: 재생고온부품 | C21: ='26년'!$Y21 -> 1804 | D21: ='27년'!$Y21 -> 16939 | E21: ='28년'!$Y21 -> 36744 | F21: ='29년'!$Y21 -> 38410 | G21: ='30년'!$Y21 -> 30919 | H21: ='31년'!$Y21 -> 144201.17 | I21: ='32년'!$Y21 -> 17583 | J21: ='33년'!$Y21 -> 35112 | K21: ='34년'!Y21 -> 31158 | L21: ='35년'!Y21 -> 18887 | M21: =SUM(C21:L21) -> 371757.17
B22: 자산화예비품 | C22: ='26년'!$Y22 -> 10656 | D22: ='27년'!$Y22 -> 3266.1286 | E22: ='28년'!$Y22 -> 6679.71 | F22: ='29년'!$Y22 -> 5537.4019 | G22: ='30년'!$Y22 -> 4808.2641 | H22: ='31년'!$Y22 -> 4889.227 | I22: ='32년'!$Y22 -> 5196.7306 | J22: ='33년'!$Y22 -> 3617.7185 | K22: ='34년'!Y22 -> 7097.3097 | L22: ='35년'!Y22 -> 5872.0628 | M22: =SUM(C22:L22) -> 57620.553
B23: 저장품 | C23: ='26년'!$Y23 -> 1296 | D23: ='27년'!$Y23 -> 724.09136 | E23: ='28년'!$Y23 -> 920.49064 | F23: ='29년'!$Y23 -> 848.8938 | G23: ='30년'!$Y23 -> 862.5597 | H23: ='31년'!$Y23 -> 1138.1824 | I23: ='32년'!$Y23 -> 765.42163 | J23: ='33년'!$Y23 -> 766 | K23: ='34년'!Y23 -> 766.5 | L23: ='35년'!Y23 -> 766.5 | M23: =SUM(C23:L23) -> 8854.6396
B24: 계 | C24: =SUM(C21:C23) -> 13756 | D24: =SUM(D21:D23) -> 20929.22 | E24: =SUM(E21:E23) -> 44344.201 | F24: =SUM(F21:F23) -> 44796.296 | G24: =SUM(G21:G23) -> 36589.824 | H24: =SUM(H21:H23) -> 150228.58 | I24: =SUM(I21:I23) -> 23545.152 | J24: =SUM(J21:J23) -> 39495.719 | ... L24: =SUM(L21:L23) -> 25525.563 | M24: =SUM(C24:L24) -> 438232.36
A25: 자본예산 합계 | C25: =C14+C15+C18+C19+C20+C24 -> 90962 | D25: =D14+D15+D18+D19+D20+D24 -> 47412.942 | E25: =E14+E15+E18+E19+E20+E24 -> 108345.48 | F25: =F14+F15+F18+F19+F20+F24 -> 90655.817 | G25: =G14+G15+G18+G19+G20+G24 -> 76183.486 | H25: =H14+H15+H18+H19+H20+H24 -> 202925.54 | I25: =I14+I15+I18+I19+I20+I24 -> 58699.717 | J25: =J14+J15+J18+J19+J20+J24 -> 69263.836 | ... M25: =M14+M15+M18+M19+M20+M24 -> 881204.86
A26: 투자비 | B26: 열원공사비 등 | C26: ='26년'!$Y26 -> 12593 | D26: ='27년'!$Y26 -> 37608.612 | E26: ='28년'!$Y26 -> 12497.592 | F26: ='29년'!$Y26 -> 12685.056 | G26: ='30년'!$Y26 -> 12875.332 | H26: ='31년'!$Y26 -> 13068.462 | I26: ='32년'!$Y26 -> 13264.489 | J26: ='33년'!$Y26 -> 13463.456 | K26: ='34년'!Y26 -> 13665.408 | L26: ='35년'!Y26 -> 13870.389 | M26: =SUM(C26:L26) -> 155591.79
N31: [단위 : 천원]
A32: 손익예산(2025중장기) | C32: 25년 | D32: 26년 | E32: 27년 | F32: 28년 | G32: 29년 | H32: 30년 | I32: 31년 | J32: 32년 | K32: 33년 | L32: 34년 | M32: 35년 | N32: 합계
A33: 수선유지비 | B33: 건물/구축물 | C33: 5701000 | D33: 2694046 | E33: 2749161 | F33: 2806509 | G33: 2897385 | H33: 3042681 | I33: 3150236 | J33: 3355134 | K33: 3557305 | L33: 3820528 | N33: =SUM(C33:L33) -> 33773985
B34: 열원정기점검 | C34: 25374000 | D34: 30376472 | E34: 25190155 | F34: 29860119 | G34: 27005853 | H34: 27681421 | I34: 25099692 | J34: 29294562 | K34: 27771028 | L34: 27013513 | N34: =SUM(C34:L34) -> 274666815
B35: 열원경상정비 | C35: 42214000 | D35: 44648210 | E35: 45247898 | F35: 47765508 | G35: 48658740 | H35: 49628431 | I35: 50689902 | J35: 51863884 | K35: 53178415 | L35: 54671559 | N35: =SUM(C35:L35) -> 488566547
B36: 열원정기유지보수 | C36: 10910000 | D36: 10622779 | E36: 10779426 | F36: 10984997 | G36: 11148087 | H36: 11313114 | I36: 9194105 | J36: 9332092 | K36: 9472103 | L36: 9614170 | N36: =SUM(C36:L36) -> 103370873
B37: 열원보완및개선 | C37: 14774000 | D37: 13602256 | E37: 14262535 | F37: 18641590 | G37: 16465844 | H37: 13300349 | I37: 18125830 | J37: 14594278 | K37: 15921342 | L37: 15063257 | N37: =SUM(C37:L37) -> 154751281
B38: 계 | C38: =SUM(C33:C37) -> 98973000 | D38: =SUM(D33:D37) -> 101943763 | E38: =SUM(E33:E37) -> 98229175 | F38: =SUM(F33:F37) -> 110058723 | G38: =SUM(G33:G37) -> 106175909 | H38: =SUM(H33:H37) -> 104965996 | I38: =SUM(I33:I37) -> 106259765 | J38: =SUM(J33:J37) -> 108439950 | ... L38: =SUM(L33:L37) -> 110183027 | N38: =SUM(N33:N37) -> 1055129501
A39: 지급수수료 | B39: 지급수수료 열원 | C39: 6676000 | D39: 6525589 | E39: 6621723 | F39: 7195220 | G39: 7303149 | H39: 7412696 | I39: 7523886 | J39: 7636745 | K39: 7751296 | L39: 7867565 | N39: =SUM(C39:L39) -> 72513869
A40: 손익예산 합계 | C40: =C38+C39 -> 105649000 | D40: =D38+D39 -> 108469352 | E40: =E38+E39 -> 104850898 | F40: =F38+F39 -> 117253943 | G40: =G38+G39 -> 113479058 | H40: =H38+H39 -> 112378692 | I40: =I38+I39 -> 113783651 | J40: =J38+J39 -> 116076695 | ... L40: =L38+L39 -> 118050592 | N40: =N38+N39 -> 1127643370
A42: 손익예산(2026중장기) | C42: 25년 | D42: 26년 | E42: 27년 | F42: 28년 | G42: 29년 | H42: 30년 | I42: 31년 | J42: 32년 | K42: 33년 | L42: 34년 | M42: 35년 | N42: 합계
A43: 수선유지비 | B43: 건물/구축물 | D43: =TRUNC(C4*1000) -> 4188000 | E43: =TRUNC(D4*1000) -> 4250820 | F43: =TRUNC(E4*1000) -> 4314582 | G43: =TRUNC(F4*1000) -> 4465046 | H43: =TRUNC(G4*1000) -> 4532022 | I43: =TRUNC(H4*1000) -> 4600002 | J43: =TRUNC(I4*1000) -> 4669002 | K43: =TRUNC(J4*1000) -> 4739037 | ... M43: =TRUNC(L4*1000) -> 4882275 | N43: =SUM(D43:M43) -> 45450909
B44: 열원정기점검 | D44: =TRUNC(C5*1000) -> 27778000 | E44: =TRUNC(D5*1000) -> 24868567 | F44: =TRUNC(E5*1000) -> 28397670 | G44: =TRUNC(F5*1000) -> 27126644 | H44: =TRUNC(G5*1000) -> 23929804 | I44: =TRUNC(H5*1000) -> 27692359 | J44: =TRUNC(I5*1000) -> 25202829 | K44: =TRUNC(J5*1000) -> 27981359 | ... M44: =TRUNC(L5*1000) -> 28620527 | N44: =SUM(D44:M44) -> 267937772
B45: 열원경상정비 | D45: =TRUNC(C6*1000) -> 42740000 | E45: =TRUNC(D6*1000) -> 44031816 | F45: =TRUNC(E6*1000) -> 46525367 | G45: =TRUNC(F6*1000) -> 47223248 | H45: =TRUNC(G6*1000) -> 47931597 | I45: =TRUNC(H6*1000) -> 48650571 | J45: =TRUNC(I6*1000) -> 49380329 | K45: =TRUNC(J6*1000) -> 50121034 | ... M45: =TRUNC(L6*1000) -> 51635942 | N45: =SUM(D45:M45) -> 479112754
B46: 열원정기유지보수 | D46: =TRUNC(C7*1000) -> 10084000 | E46: =TRUNC(D7*1000) -> 10962614 | F46: =TRUNC(E7*1000) -> 11112848 | G46: =TRUNC(F7*1000) -> 10505577 | H46: =TRUNC(G7*1000) -> 10660951 | I46: =TRUNC(H7*1000) -> 8532145 | J46: =TRUNC(I7*1000) -> 8660187 | K46: =TRUNC(J7*1000) -> 8790105 | ... M46: =TRUNC(L7*1000) -> 9004284 | N46: =SUM(D46:M46) -> 97234638
...

Sheet 26년
Y2: [단위 : 백만원]
A3: 2026년 | C3: 동탄 | D3: 화성 | E3: 파주 | F3: 광교 | G3: 판교 | H3: 삼송 | I3: 양산 | J3: 대구 | K3: 청주 | L3: 소계 | M3: 수원 | N3: 광주전남 | O3: 강남 | P3: 소계 | Q3: 중앙 | R3: 고양 | S3: 용인 | T3: 분당 | U3: 세종 | V3: 김해 | W3: 평택 | X3: 소계 | Y3: 합계
A4: 수선유지비 | B4: 건물/구축물 | C4: =동탄!C6 -> 951 | D4: =화성!C6 -> 367 | E4: =파주!C6 -> 792 | F4: =광교!C6 -> 44 | G4: =판교!C6 -> 306 | H4: =삼송!C6 -> 287 | I4: =양산!C6 -> 163 | J4: =대구!C6 -> 3 | K4: =청주!C6 -> 30 | L4: =SUM(C4:K4) -> 2943 | M4: =수원!C6 -> 224 | N4: =광주전남!C6 -> 239 | O4: =강남!C6 -> 161 | P4: =SUM(M4:O4) -> 624 | Q4: =중앙!C6 -> 207 | R4: =고양!C6 -> 106 | S4: =용인!C6 -> 86 | T4: =분당!C6 -> 40 | U4: =세종!C6 -> 32 | V4: =김해!C6 -> 150 | W4: =평택!C6 -> 0 | X4: =SUM(Q4:W4) -> 621 | Y4: =L4+P4+X4 -> 4188
B5: 열원정기점검 | C5: =동탄!C7 -> 6867 | D5: =화성!C7 -> 1061 | E5: =파주!C7 -> 4021 | F5: =광교!C7 -> 1391 | G5: =판교!C7 -> 706 | H5: =삼송!C7 -> 1477 | I5: =양산!C7 -> 811 | J5: =대구!C7 -> 2118 | K5: =청주!C7 -> 1763 | L5: =SUM(C5:K5) -> 20215 | M5: =수원!C7 -> 872 | N5: =광주전남!C7 -> 1213 | O5: =강남!C7 -> 1829 | P5: =SUM(M5:O5) -> 3914 | Q5: =중앙!C7 -> 1344 | R5: =고양!C7 -> 635 | S5: =용인!C7 -> 472 | T5: =분당!C7 -> 611 | U5: =세종!C7 -> 114 | V5: =김해!C7 -> 308 | W5: =평택!C7 -> 165 | X5: =SUM(Q5:W5) -> 3649 | Y5: =L5+P5+X5 -> 27778
B6: 열원경상정비 | C6: =동탄!C8 -> 7974 | D6: =화성!C8 -> 6160 | E6: =파주!C8 -> 5757 | F6: =광교!C8 -> 2366 | G6: =판교!C8 -> 2456 | H6: =삼송!C8 -> 1772 | I6: =양산!C8 -> 2208 | J6: =대구!C8 -> 3653 | K6: =청주!C8 -> 3319 | L6: =SUM(C6:K6) -> 35665 | M6: =수원!C8 -> 703 | N6: =광주전남!C8 -> 1748 | O6: =강남!C8 -> 1227 | P6: =SUM(M6:O6) -> 3678 | Q6: =중앙!C8 -> 1064 | R6: =고양!C8 -> 699 | S6: =용인!C8 -> 677 | T6: =분당!C8 -> 604 | U6: =세종!C8 -> 273 | V6: =김해!C8 -> 40 | W6: =평택!C8 -> 40 | X6: =SUM(Q6:W6) -> 3397 | Y6: =L6+P6+X6 -> 42740
B7: 열원정기유지보수 | C7: =동탄!C9 -> 5248 | D7: =화성!C9 -> 372 | E7: =파주!C9 -> 647 | F7: =광교!C9 -> 188 | G7: =판교!C9 -> 188 | H7: =삼송!C9 -> 159 | I7: =양산!C9 -> 233 | J7: =대구!C9 -> 266 | K7: =청주!C9 -> 203 | L7: =SUM(C7:K7) -> 7504 | M7: =수원!C9 -> 150 | N7: =광주전남!C9 -> 208 | O7: =강남!C9 -> 587 | P7: =SUM(M7:O7) -> 945 | Q7: =중앙!C9 -> 687 | R7: =고양!C9 -> 538 | S7: =용인!C9 -> 119 | T7: =분당!C9 -> 84 | U7: =세종!C9 -> 61 | V7: =김해!C9 -> 53 | W7: =평택!C9 -> 93 | X7: =SUM(Q7:W7) -> 1635 | Y7: =L7+P7+X7 -> 10084
B8: 열원보완및개선 | C8: =동탄!C10 -> 3214 | D8: =화성!C10 -> 1224 | E8: =파주!C10 -> 1455 | F8: =광교!C10 -> 1242 | G8: =판교!C10 -> 469 | H8: =삼송!C10 -> 392 | I8: =양산!C10 -> 895 | J8: =대구!C10 -> 772 | K8: =청주!C10 -> 372 | L8: =SUM(C8:K8) -> 10035 | M8: =수원!C10 -> 290 | N8: =광주전남!C10 -> 712 | O8: =강남!C10 -> 637 | P8: =SUM(M8:O8) -> 1639 | Q8: =중앙!C10 -> 1052 | R8: =고양!C10 -> 1248 | S8: =용인!C10 -> 223 | T8: =분당!C10 -> 444 | U8: =세종!C10 -> 335 | V8: =김해!C10 -> 264 | W8: =평택!C10 -> 28 | X8: =SUM(Q8:W8) -> 3594 | Y8: =L8+P8+X8 -> 15268
B9: 비저장품(보수자재) | C9: =동탄!C11 -> 280 | D9: =화성!C11 -> 216 | E9: =파주!C11 -> 202 | F9: =광교!C11 -> 83 | G9: =판교!C11 -> 86 | H9: =삼송!C11 -> 62 | I9: =양산!C11 -> 77 | J9: =대구!C11 -> 128 | K9: =청주!C11 -> 117 | L9: =SUM(C9:K9) -> 1251 | M9: =수원!C11 -> 25 | N9: =광주전남!C11 -> 61 | O9: =강남!C11 -> 43 | P9: =SUM(M9:O9) -> 129 | Q9: =중앙!C11 -> 37 | R9: =고양!C11 -> 25 | S9: =용인!C11 -> 24 | T9: =분당!C11 -> 21 | U9: =세종!C11 -> 10 | V9: =김해!C11 -> 1 | W9: =평택!C11 -> 1 | X9: =SUM(Q9:W9) -> 119 | Y9: =L9+P9+X9 -> 1499
B10: 소모품(자재공기구) | C10: =동탄!C12 -> 37 | D10: =화성!C12 -> 29 | E10: =파주!C12 -> 27 | F10: =광교!C12 -> 11 | G10: =판교!C12 -> 11 | H10: =삼송!C12 -> 8 | I10: =양산!C12 -> 10 | J10: =대구!C12 -> 17 | K10: =청주!C12 -> 16 | L10: =SUM(C10:K10) -> 166 | M10: =수원!C12 -> 3 | N10: =광주전남!C12 -> 8 | O10: =강남!C12 -> 6 | P10: =SUM(M10:O10) -> 17 | Q10: =중앙!C12 -> 5 | R10: =고양!C12 -> 3 | S10: =용인!C12 -> 3 | T10: =분당!C12 -> 3 | U10: =세종!C12 -> 1 | V10: =김해!C12 -> 0 | W10: =평택!C12 -> 0 | X10: =SUM(Q10:W10) -> 15 | Y10: =L10+P10+X10 -> 198
B11: 계 | C11: =SUM(C4:C10) -> 24571 | D11: =SUM(D4:D10) -> 9429 | E11: =SUM(E4:E10) -> 12901 | F11: =SUM(F4:F10) -> 5325 | G11: =SUM(G4:G10) -> 4222 | H11: =SUM(H4:H10) -> 4157 | I11: =SUM(I4:I10) -> 4397 | J11: =SUM(J4:J10) -> 6957 | K11: =SUM(K4:K10) -> 5820 | L11: =SUM(C11:K11) -> 77779 | M11: =SUM(M4:M10) -> 2267 | N11: =SUM(N4:N10) -> 4189 | O11: =SUM(O4:O10) -> 4490 | P11: =SUM(M11:O11) -> 10946 | Q11: =SUM(Q4:Q10) -> 4396 | R11: =SUM(R4:R10) -> 3254 | S11: =SUM(S4:S10) -> 1604 | T11: =SUM(T4:T10) -> 1807 | U11: =SUM(U4:U10) -> 826 | V11: =SUM(V4:V10) -> 816 | W11: =SUM(W4:W10) -> 327 | X11: =SUM(Q11:W11) -> 13030 | Y11: =L11+P11+X11 -> 101755
A12: 지급수수료 | B12: 지급수수료 열원 | C12: =동탄!C13 -> 619 | D12: =화성!C13 -> 369 | E12: =파주!C13 -> 561 | F12: =광교!C13 -> 234 | G12: =판교!C13 -> 214 | H12: =삼송!C13 -> 229 | I12: =양산!C13 -> 667 | J12: =대구!C13 -> 422 | K12: =청주!C13 -> 439 | L12: =SUM(C12:K12) -> 3754 | M12: =수원!C13 -> 105 | N12: =광주전남!C13 -> 777 | O12: =강남!C13 -> 237 | P12: =SUM(M12:O12) -> 1119 | Q12: =중앙!C13 -> 238 | R12: =고양!C13 -> 100 | S12: =용인!C13 -> 191 | T12: =분당!C13 -> 65 | U12: =세종!C13 -> 78 | V12: =김해!C13 -> 160 | W12: =평택!C13 -> 51 | X12: =SUM(Q12:W12) -> 883 | Y12: =L12+P12+X12 -> 5756
A13: 손익예산 합계 | C13: =C12+C11 -> 25190 | D13: =D12+D11 -> 9798 | E13: =E12+E11 -> 13462 | F13: =F12+F11 -> 5559 | G13: =G12+G11 -> 4436 | H13: =H12+H11 -> 4386 | I13: =I12+I11 -> 5064 | J13: =J12+J11 -> 7379 | K13: =K12+K11 -> 6259 | L13: =SUM(C13:K13) -> 81533 | M13: =M12+M11 -> 2372 | N13: =N12+N11 -> 4966 | O13: =O12+O11 -> 4727 | P13: =SUM(M13:O13) -> 12065 | Q13: =Q12+Q11 -> 4634 | R13: =R12+R11 -> 3354 | S13: =S12+S11 -> 1795 | T13: =T12+T11 -> 1872 | U13: =U12+U11 -> 904 | V13: =V12+V11 -> 976 | W13: =W12+W11 -> 378 | X13: =SUM(Q13:W13) -> 13913 | Y13: =L13+P13+X13 -> 107511 | Z13: =Y13-'[38]26년'!$Y$11 -> 9796.7764
A14: 건물 | C14: =동탄!C15 -> 19 | D14: =화성!C15 -> 22 | E14: =파주!C15 -> 1 | F14: =광교!C15 -> 28 | G14: =판교!C15 -> 6 | H14: =삼송!C15 -> 0 | I14: =양산!C15 -> 11 | J14: =대구!C15 -> 1 | K14: =청주!C15 -> 1 | L14: =SUM(C14:K14) -> 89 | M14: =수원!C15 -> 0 | N14: =광주전남!C15 -> 0 | O14: =강남!C15 -> 0 | P14: =SUM(M14:O14) -> 0 | Q14: =중앙!C15 -> 0 | R14: =고양!C15 -> 20 | S14: =용인!C15 -> 0 | T14: =분당!C15 -> 11 | U14: =세종!C15 -> 0 | V14: =김해!C15 -> 0 | W14: =평택!C15 -> 0 | X14: =SUM(Q14:W14) -> 31 | Y14: =L14+P14+X14 -> 120
A15: 구축물 | C15: =동탄!C16 -> 0 | D15: =화성!C16 -> 0 | E15: =파주!C16 -> 50 | F15: =광교!C16 -> 0 | G15: =판교!C16 -> 0 | H15: =삼송!C16 -> 0 | I15: =양산!C16 -> 0 | J15: =대구!C16 -> 0 | K15: =청주!C16 -> 0 | L15: =SUM(C15:K15) -> 50 | M15: =수원!C16 -> 0 | N15: =광주전남!C16 -> 0 | O15: =강남!C16 -> 0 | P15: =SUM(M15:O15) -> 0 | Q15: =중앙!C16 -> 0 | R15: =고양!C16 -> 0 | S15: =용인!C16 -> 0 | T15: =분당!C16 -> 0 | U15: =세종!C16 -> 0 | V15: =김해!C16 -> 0 | W15: =평택!C16 -> 0 | X15: =SUM(Q15:W15) -> 0 | Y15: =L15+P15+X15 -> 50
A16: 기계장치 | B16: 고온부품재생+LTSA | C16: =동탄!C17 -> 12336 | D16: =화성!C17 -> 2162 | E16: =파주!C17 -> 894 | F16: =광교!C17 -> 1327 | G16: =판교!C17 -> 0 | H16: =삼송!C17 -> 0 | I16: =양산!C17 -> 0 | J16: =대구!C17 -> 0 | K16: =청주!C17 -> 0 | L16: =SUM(C16:K16) -> 16719 | M16: =수원!C17 -> 0 | N16: =광주전남!C17 -> 0 | O16: =강남!C17 -> 0 | P16: =SUM(M16:O16) -> 0 | Q16: =중앙!C17 -> 0 | R16: =고양!C17 -> 0 | S16: =용인!C17 -> 0 | T16: =분당!C17 -> 0 | U16: =세종!C17 -> 0 | V16: =김해!C17 -> 0 | W16: =평택!C17 -> 0 | X16: =SUM(Q16:W16) -> 0 | Y16: =L16+P16+X16 -> 16719
B17: 기타기계장치 | C17: =동탄!C18 -> 5696 | D17: =화성!C18 -> 5727 | E17: =파주!C18 -> 6420 | F17: =광교!C18 -> 7345 | G17: =판교!C18 -> 3678 | H17: =삼송!C18 -> 1196 | I17: =양산!C18 -> 4141 | J17: =대구!C18 -> 4729 | K17: =청주!C18 -> 802 | L17: =SUM(C17:K17) -> 39734 | M17: =수원!C18 -> 960 | N17: =광주전남!C18 -> 2701 | O17: =강남!C18 -> 1351 | P17: =SUM(M17:O17) -> 5012 | Q17: =중앙!C18 -> 3447 | R17: =고양!C18 -> 4511 | S17: =용인!C18 -> 1504 | T17: =분당!C18 -> 2098 | U17: =세종!C18 -> 128 | V17: =김해!C18 -> 1 | W17: =평택!C18 -> 6 | X17: =SUM(Q17:W17) -> 11695 | Y17: =L17+P17+X17 -> 56441
B18: 계 | C18: =SUM(C16:C17) -> 18032 | D18: =SUM(D16:D17) -> 7889 | E18: =SUM(E16:E17) -> 7314 | F18: =SUM(F16:F17) -> 8672 | G18: =SUM(G16:G17) -> 3678 | H18: =SUM(H16:H17) -> 1196 | I18: =SUM(I16:I17) -> 4141 | J18: =SUM(J16:J17) -> 4729 | K18: =SUM(K16:K17) -> 802 | L18: =SUM(C18:K18) -> 56453 | M18: =SUM(M16:M17) -> 960 | N18: =SUM(N16:N17) -> 2701 | O18: =SUM(O16:O17) -> 1351 | P18: =SUM(M18:O18) -> 5012 | Q18: =SUM(Q16:Q17) -> 3447 | R18: =SUM(R16:R17) -> 4511 | S18: =SUM(S16:S17) -> 1504 | T18: =SUM(T16:T17) -> 2098 | U18: =SUM(U16:U17) -> 128 | V18: =SUM(V16:V17) -> 1 | W18: =SUM(W16:W17) -> 6 | X18: =SUM(Q18:W18) -> 11695 | Y18: =L18+P18+X18 -> 73160
A19: 건가-외주비 | B19: MI 및 A급 정비 | C19: =동탄!C19 -> 0 | D19: =화성!C19 -> 0 | E19: =파주!C19 -> 600 | F19: =광교!C19 -> 0 | G19: =판교!C19 -> 690 | H19: =삼송!C19 -> 0 | I19: =양산!C19 -> 0 | J19: =대구!C19 -> 0 | K19: =청주!C19 -> 0 | L19: =SUM(C19:K19) -> 1290 | M19: =수원!C19 -> 0 | N19: =광주전남!C19 -> 702 | O19: =강남!C19 -> 400 | P19: =SUM(M19:O19) -> 1102 | Q19: =중앙!C19 -> 0 | R19: =고양!C19 -> 0 | S19: =용인!C19 -> 0 | T19: =분당!C19 -> 0 | U19: =세종!C19 -> 0 | V19: =김해!C19 -> 0 | W19: =평택!C19 -> 0 | X19: =SUM(Q19:W19) -> 0 | Y19: =L19+P19+X19 -> 2392
A20: 공구와기구 | C20: =동탄!C20 -> 158 | D20: =화성!C20 -> 77 | E20: =파주!C20 -> 413 | F20: =광교!C20 -> 26 | G20: =판교!C20 -> 4 | H20: =삼송!C20 -> 0 | I20: =양산!C20 -> 452 | J20: =대구!C20 -> 152 | K20: =청주!C20 -> 127 | L20: =SUM(C20:K20) -> 1409 | M20: =수원!C20 -> 29 | N20: =광주전남!C20 -> 0 | O20: =강남!C20 -> 9 | P20: =SUM(M20:O20) -> 38 | Q20: =중앙!C20 -> 0 | R20: =고양!C20 -> 21 | S20: =용인!C20 -> 10 | T20: =분당!C20 -> 6 | U20: =세종!C20 -> 0 | V20: =김해!C20 -> 0 | W20: =평택!C20 -> 0 | X20: =SUM(Q20:W20) -> 37 | Y20: =L20+P20+X20 -> 1484
A21: 예비품 | B21: 재생고온부품 | C21: =동탄!C21 -> 0 | D21: =화성!C21 -> 0 | E21: =파주!C21 -> 1304 | F21: =광교!C21 -> 0 | G21: =판교!C21 -> 500 | H21: =삼송!C21 -> 0 | I21: =양산!C21 -> 0 | J21: =대구!C21 -> 0 | K21: =청주!C21 -> 0 | L21: =SUM(C21:K21) -> 1804 | M21: =수원!C21 -> 0 | N21: =광주전남!C21 -> 0 | O21: =강남!C21 -> 0 | P21: =SUM(M21:O21) -> 0 | Q21: =중앙!C21 -> 0 | R21: =고양!C21 -> 0 | S21: =용인!C21 -> 0 | T21: =분당!C21 -> 0 | U21: =세종!C21 -> 0 | V21: =김해!C21 -> 0 | W21: =평택!C21 -> 0 | X21: =SUM(Q21:W21) -> 0 | Y21: =L21+P21+X21 -> 1804
B22: 자산화예비품 | C22: =동탄!C22 -> 2498 | D22: =화성!C22 -> 536 | E22: =파주!C22 -> 1939 | F22: =광교!C22 -> 824 | G22: =판교!C22 -> 535 | H22: =삼송!C22 -> 1519 | I22: =양산!C22 -> 1467 | J22: =대구!C22 -> 185 | K22: =청주!C22 -> 627 | L22: =SUM(C22:K22) -> 10130 | M22: =수원!C22 -> 0 | N22: =광주전남!C22 -> 345 | O22: =강남!C22 -> 17 | P22: =SUM(M22:O22) -> 362 | Q22: =중앙!C22 -> 29 | R22: =고양!C22 -> 0 | S22: =용인!C22 -> 0 | T22: =분당!C22 -> 0 | U22: =세종!C22 -> 135 | V22: =김해!C22 -> 0 | W22: =평택!C22 -> 0 | X22: =SUM(Q22:W22) -> 164 | Y22: =L22+P22+X22 -> 10656
B23: 저장품 | C23: =동탄!C23 -> 1 | D23: =화성!C23 -> 71 | E23: =파주!C23 -> 343 | F23: =광교!C23 -> 398 | G23: =판교!C23 -> 175 | H23: =삼송!C23 -> 160 | I23: =양산!C23 -> 91 | J23: =대구!C23 -> 42 | K23: =청주!C23 -> 0 | L23: =SUM(C23:K23) -> 1281 | M23: =수원!C23 -> 0 | N23: =광주전남!C23 -> 0 | O23: =강남!C23 -> 0 | P23: =SUM(M23:O23) -> 0 | Q23: =중앙!C23 -> 0 | R23: =고양!C23 -> 10 | S23: =용인!C23 -> 0 | T23: =분당!C23 -> 0 | U23: =세종!C23 -> 0 | V23: =김해!C23 -> 0 | W23: =평택!C23 -> 5 | X23: =SUM(Q23:W23) -> 15 | Y23: =L23+P23+X23 -> 1296
B24: 계 | C24: =SUM(C21:C23) -> 2499 | D24: =SUM(D21:D23) -> 607 | E24: =SUM(E21:E23) -> 3586 | F24: =SUM(F21:F23) -> 1222 | G24: =SUM(G21:G23) -> 1210 | H24: =SUM(H21:H23) -> 1679 | I24: =SUM(I21:I23) -> 1558 | J24: =SUM(J21:J23) -> 227 | K24: =SUM(K21:K23) -> 627 | L24: =SUM(C24:K24) -> 13215 | M24: =SUM(M21:M23) -> 0 | N24: =SUM(N21:N23) -> 345 | O24: =SUM(O21:O23) -> 17 | P24: =SUM(M24:O24) -> 362 | Q24: =SUM(Q21:Q23) -> 29 | R24: =SUM(R21:R23) -> 10 | S24: =SUM(S21:S23) -> 0 | T24: =SUM(T21:T23) -> 0 | U24: =SUM(U21:U23) -> 135 | V24: =SUM(V21:V23) -> 0 | W24: =SUM(W21:W23) -> 5 | X24: =SUM(Q24:W24) -> 179 | Y24: =L24+P24+X24 -> 13756
A25: 자본예산 합계 | C25: =C14+C15+C19+C18+C20+C24 -> 20708 | D25: =D14+D15+D19+D18+D20+D24 -> 8595 | E25: =E14+E15+E19+E18+E20+E24 -> 11964 | F25: =F14+F15+F19+F18+F20+F24 -> 9948 | G25: =G14+G15+G19+G18+G20+G24 -> 5588 | H25: =H14+H15+H19+H18+H20+H24 -> 2875 | I25: =I14+I15+I19+I18+I20+I24 -> 6162 | J25: =J14+J15+J19+J18+J20+J24 -> 5109 | ... Y25: =Y14+Y15+Y19+Y18+Y20+Y24 -> 90962 | Z25: =Y25-'[38]26년'!$Y$23 -> 42545.156
A26: 투자비 | B26: 열원공사비 등 | C26: =동탄!C25 -> 3370 | D26: =화성!C25 -> 0 | E26: =파주!C25 -> 0 | F26: =광교!C25 -> 0 | G26: =판교!C25 -> 4194 | H26: =삼송!C25 -> 0 | I26: =양산!C25 -> 0 | J26: =대구!C25 -> 0 | K26: =청주!C25 -> 1696 | L26: =SUM(C26:K26) -> 9260 | M26: =수원!C25 -> 130 | N26: =광주전남!C25 -> 0 | O26: =강남!C25 -> 3203 | P26: =SUM(M26:O26) -> 3333 | Q26: =중앙!C25 -> 0 | R26: =고양!C25 -> 0 | S26: =용인!C25 -> 0 | T26: =분당!C25 -> 0 | U26: =세종!C25 -> 0 | V26: =김해!C25 -> 0 | W26: =평택!C25 -> 0 | X26: =SUM(Q26:W26) -> 0 | Y26: =L26+P26+X26 -> 12593
B31: 건물/구축물 | C31: 661 | D31: 367 | E31: 432 | F31: 44 | G31: 206 | H31: 267 | I31: 163 | J31: 3 | K31: 30 | L31: 2173 | M31: 224 | N31: 39 | O31: 161 | P31: 424 | Q31: 207 | R31: 106 | S31: 86 | T31: 40 | U31: 32 | V31: 150 | W31: 0
B32: 열원정기점검 | C32: 6647 | D32: 1061 | E32: 3970 | F32: 1391 | G32: 706 | H32: 1477 | I32: 811 | J32: 2118 | K32: 1763 | L32: 19944 | M32: 872 | N32: 1213 | O32: 1829 | P32: 3914 | Q32: 1344 | R32: 635 | S32: 472 | T32: 611 | U32: 114 | V32: 308 | W32: 165
B33: 열원경상정비 | C33: 7774 | D33: 5910 | E33: 5657 | F33: 2366 | G33: 2456 | H33: 1772 | I33: 2208 | J33: 3603 | K33: 3269 | L33: 35015 | M33: 703 | N33: 1748 | O33: 1227 | P33: 3678 | Q33: 1064 | R33: 699 | S33: 677 | T33: 604 | U33: 273 | V33: 40 | W33: 40
B34: 열원정기유지보수 | C34: 4974 | D34: 372 | E34: 618 | F34: 175 | G34: 188 | H34: 159 | I34: 196 | J34: 266 | K34: 203 | L34: 7151 | M34: 150 | N34: 208 | O34: 587 | P34: 945 | Q34: 687 | R34: 538 | S34: 119 | T34: 84 | U34: 61 | V34: 53 | W34: 93
B35: 열원보완및개선 | C35: 2940 | D35: 1137 | E35: 1447 | F35: 1208 | G35: 454 | H35: 315 | I35: 775 | J35: 769 | K35: 310 | L35: 9355 | M35: 246 | N35: 712 | O35: 349 | P35: 1307 | Q35: 711 | R35: 1199 | S35: 219 | T35: 442 | U35: 282 | V35: 264 | W35: 28
B36: 비저장품(보수자재) | C36: 280 | D36: 216 | E36: 202 | F36: 83 | G36: 86 | H36: 62 | I36: 77 | J36: 128 | K36: 117 | L36: 1251 | M36: 25 | N36: 61 | O36: 43 | P36: 129 | Q36: 37 | R36: 25 | S36: 24 | T36: 21 | U36: 10 | V36: 1 | W36: 1
B37: 소모품(자재공기구) | C37: 37 | D37: 29 | E37: 27 | F37: 11 | G37: 11 | H37: 8 | I37: 10 | J37: 17 | K37: 16 | L37: 166 | M37: 3 | N37: 8 | O37: 6 | P37: 17 | Q37: 5 | R37: 3 | S37: 3 | T37: 3 | U37: 1 | V37: 0 | W37: 0
B39: 지급수수료 열원 | C39: 558 | D39: 369 | E39: 492 | F39: 196 | G39: 208 | H39: 227 | I39: 624 | J39: 422 | K39: 439 | L39: 3535 | M39: 101 | N39: 766 | O39: 237 | P39: 1104 | Q39: 238 | R39: 85 | S39: 163 | T39: 65 | U39: 78 | V39: 152 | W39: 41
C41: 19 | D41: 22 | E41: 1 | F41: 28 | G41: 6 | H41: 0 | I41: 11 | J41: 1 | K41: 1 | L41: 89 | M41: 0 | N41: 0 | O41: 0 | P41: 0 | Q41: 0 | R41: 20 | S41: 0 | T41: 11 | U41: 0 | V41: 0 | W41: 0
C42: 0 | D42: 0 | E42: 50 | F42: 0 | G42: 0 | H42: 0 | I42: 0 | J42: 0 | K42: 0 | L42: 50 | M42: 0 | N42: 0 | O42: 0 | P42: 0 | Q42: 0 | R42: 0 | S42: 0 | T42: 0 | U42: 0 | V42: 0 | W42: 0
C43: 12336 | D43: 2162 | E43: 894 | F43: 1327 | G43: 0 | H43: 0 | I43: 0 | J43: 0 | K43: 0 | L43: 16719 | M43: 0 | N43: 0 | O43: 0 | P43: 0 | Q43: 0 | R43: 0 | S43: 0 | T43: 0 | U43: 0 | V43: 0 | W43: 0
C44: 5696 | D44: 5727 | E44: 6420 | F44: 7345 | G44: 3678 | H44: 1196 | I44: 4141 | J44: 4729 | K44: 802 | L44: 39734 | M44: 960 | N44: 2701 | O44: 1351 | P44: 5012 | Q44: 3447 | R44: 4511 | S44: 1504 | T44: 2098 | U44: 128 | V44: 1 | W44: 6
C46: 0 | D46: 0 | E46: 600 | F46: 0 | G46: 690 | H46: 0 | I46: 0 | J46: 0 | K46: 0 | L46: 1290 | M46: 0 | N46: 702 | O46: 400 | P46: 1102 | Q46: 0 | R46: 0 | S46: 0 | T46: 0 | U46: 0 | V46: 0 | W46: 0
C47: 158 | D47: 77 | E47: 413 | F47: 26 | G47: 4 | H47: 0 | I47: 452 | J47: 152 | K47: 127 | L47: 1409 | M47: 29 | N47: 0 | O47: 9 | P47: 38 | Q47: 0 | R47: 21 | S47: 10 | T47: 6 | U47: 0 | V47: 0 | W47: 0
C48: 0 | D48: 0 | E48: 1304 | F48: 0 | G48: 500 | H48: 0 | I48: 0 | J48: 0 | K48: 0 | L48: 1804 | M48: 0 | N48: 0 | O48: 0 | P48: 0 | Q48: 0 | R48: 0 | S48: 0 | T48: 0 | U48: 0 | V48: 0 | W48: 0
...

Sheet 27년
Y2: [단위 : 백만원]
A3: 2027년 | C3: 동탄 | D3: 화성 | E3: 파주 | F3: 광교 | G3: 판교 | H3: 삼송 | I3: 양산 | J3: 대구 | K3: 청주 | L3: 소계 | M3: 수원 | N3: 광주전남 | O3: 강남 | P3: 소계 | Q3: 중앙 | R3: 고양 | S3: 용인 | T3: 분당 | U3: 세종 | V3: 김해 | W3: 평택 | X3: 소계 | Y3: 합계
A4: 수선유지비 | B4: 건물/구축물 | C4: =동탄!D6 -> 965.265 | D4: =화성!D6 -> 372.505 | E4: =파주!D6 -> 803.88 | F4: =광교!D6 -> 44.66 | G4: =판교!D6 -> 310.59 | H4: =삼송!D6 -> 291.305 | I4: =양산!D6 -> 165.445 | J4: =대구!D6 -> 3.045 | K4: =청주!D6 -> 30.45 | L4: =SUM(C4:K4) -> 2987.145 | M4: =수원!D6 -> 227.36 | N4: =광주전남!D6 -> 242.585 | O4: =강남!D6 -> 163.415 | P4: =SUM(M4:O4) -> 633.36 | Q4: =중앙!D6 -> 210.105 | R4: =고양!D6 -> 107.59 | S4: =용인!D6 -> 87.29 | T4: =분당!D6 -> 40.6 | U4: =세종!D6 -> 32.48 | V4: =김해!D6 -> 152.25 | W4: =평택!D6 -> 0 | X4: =SUM(Q4:W4) -> 630.315 | Y4: =L4+P4+X4 -> 4250.82
B5: 열원정기점검 | C5: =동탄!D7 -> 3355.5819 | D5: =화성!D7 -> 3898.1252 | E5: =파주!D7 -> 2118.4816 | F5: =광교!D7 -> 965.84083 | G5: =판교!D7 -> 864.77602 | H5: =삼송!D7 -> 640.79995 | I5: =양산!D7 -> 1733.35 | J5: =대구!D7 -> 2506.6448 | K5: =청주!D7 -> 1108.5221 | L5: =SUM(C5:K5) -> 17192.122 | M5: =수원!D7 -> 885.08 | N5: =광주전남!D7 -> 1231.195 | O5: =강남!D7 -> 1856.435 | P5: =SUM(M5:O5) -> 3972.71 | Q5: =중앙!D7 -> 1364.16 | R5: =고양!D7 -> 644.525 | S5: =용인!D7 -> 479.08 | T5: =분당!D7 -> 620.165 | U5: =세종!D7 -> 115.71 | V5: =김해!D7 -> 312.62 | W5: =평택!D7 -> 167.475 | X5: =SUM(Q5:W5) -> 3703.735 | Y5: =L5+P5+X5 -> 24868.567
B6: 열원경상정비 | C6: =동탄!D8 -> 8215.0141 | D6: =화성!D8 -> 6346.186 | E6: =파주!D8 -> 5931.0053 | F6: =광교!D8 -> 2437.5123 | G6: =판교!D8 -> 2530.2326 | H6: =삼송!D8 -> 1825.5587 | I6: =양산!D8 -> 2274.7368 | J6: =대구!D8 -> 3763.4119 | K6: =청주!D8 -> 3419.3168 | L6: =SUM(C6:K6) -> 36742.975 | M6: =수원!D8 -> 724.24817 | N6: =광주전남!D8 -> 1800.8333 | O6: =강남!D8 -> 1264.0861 | P6: =SUM(M6:O6) -> 3789.1675 | Q6: =중앙!D8 -> 1096.1594 | R6: =고양!D8 -> 720.12727 | S6: =용인!D8 -> 697.46232 | T6: =분당!D8 -> 622.2559 | U6: =세종!D8 -> 281.25142 | V6: =김해!D8 -> 41.209 | W6: =평택!D8 -> 41.209 | X6: =SUM(Q6:W6) -> 3499.6743 | Y6: =L6+P6+X6 -> 44031.816
B7: 열원정기유지보수 | C7: =동탄!D9 -> 5254.0748 | D7: =화성!D9 -> 377.58 | E7: =파주!D9 -> 656.705 | F7: =광교!D9 -> 990.82 | G7: =판교!D9 -> 190.82 | H7: =삼송!D9 -> 161.385 | I7: =양산!D9 -> 236.495 | J7: =대구!D9 -> 269.99 | K7: =청주!D9 -> 206.045 | L7: =SUM(C7:K7) -> 8343.9148 | M7: =수원!D9 -> 152.25 | N7: =광주전남!D9 -> 211.12 | O7: =강남!D9 -> 595.805 | P7: =SUM(M7:O7) -> 959.175 | Q7: =중앙!D9 -> 697.305 | R7: =고양!D9 -> 546.07 | S7: =용인!D9 -> 120.785 | T7: =분당!D9 -> 85.26 | U7: =세종!D9 -> 61.915 | V7: =김해!D9 -> 53.795 | W7: =평택!D9 -> 94.395 | X7: =SUM(Q7:W7) -> 1659.525 | Y7: =L7+P7+X7 -> 10962.615
B8: 열원보완및개선 | C8: =동탄!D10 -> 2343.6967 | D8: =화성!D10 -> 1242.36 | E8: =파주!D10 -> 729.15676 | F8: =광교!D10 -> 1260.63 | G8: =판교!D10 -> 476.035 | H8: =삼송!D10 -> 397.88 | I8: =양산!D10 -> 908.425 | J8: =대구!D10 -> 783.58 | K8: =청주!D10 -> 377.58 | L8: =SUM(C8:K8) -> 8519.3435 | M8: =수원!D10 -> 294.35 | N8: =광주전남!D10 -> 722.68 | O8: =강남!D10 -> 646.555 | P8: =SUM(M8:O8) -> 1663.585 | Q8: =중앙!D10 -> 1067.78 | R8: =고양!D10 -> 1266.72 | S8: =용인!D10 -> 226.345 | T8: =분당!D10 -> 450.66 | U8: =세종!D10 -> 340.025 | V8: =김해!D10 -> 267.96 | W8: =평택!D10 -> 28.42 | X8: =SUM(Q8:W8) -> 3647.91 | Y8: =L8+P8+X8 -> 13830.838
B9: 비저장품(보수자재) | C9: =동탄!D11 -> 754.145 | D9: =화성!D11 -> 582.61 | E9: =파주!D11 -> 544.04 | F9: =광교!D11 -> 223.3 | G9: =판교!D11 -> 232.435 | H9: =삼송!D11 -> 50.75 | I9: =양산!D11 -> 208.075 | J9: =대구!D11 -> 345.1 | K9: =청주!D11 -> 313.635 | L9: =SUM(C9:K9) -> 3254.09 | M9: =수원!D11 -> 63.945 | N9: =광주전남!D11 -> 159.355 | O9: =강남!D11 -> 111.65 | P9: =SUM(M9:O9) -> 334.95 | Q9: =중앙!D11 -> 97.44 | R9: =고양!D11 -> 63.945 | S9: =용인!D11 -> 61.915 | T9: =분당!D11 -> 54.81 | U9: =세종!D11 -> 25.375 | V9: =김해!D11 -> 4.06 | W9: =평택!D11 -> 4.06 | X9: =SUM(Q9:W9) -> 311.605 | Y9: =L9+P9+X9 -> 3900.645
B10: 소모품(자재공기구) | C10: =동탄!D12 -> 84.245 | D10: =화성!D12 -> 64.96 | E10: =파주!D12 -> 60.9 | F10: =광교!D12 -> 24.36 | G10: =판교!D12 -> 25.375 | H10: =삼송!D12 -> 6.09 | I10: =양산!D12 -> 23.345 | J10: =대구!D12 -> 38.57 | K10: =청주!D12 -> 34.51 | L10: =SUM(C10:K10) -> 362.355 | M10: =수원!D12 -> 7.105 | N10: =광주전남!D12 -> 17.255 | O10: =강남!D12 -> 12.18 | P10: =SUM(M10:O10) -> 36.54 | Q10: =중앙!D12 -> 11.165 | R10: =고양!D12 -> 7.105 | S10: =용인!D12 -> 7.105 | T10: =분당!D12 -> 6.09 | U10: =세종!D12 -> 3.045 | V10: =김해!D12 -> 1.015 | W10: =평택!D12 -> 1.015 | X10: =SUM(Q10:W10) -> 36.54 | Y10: =L10+P10+X10 -> 435.435
B11: 계 | C11: =SUM(C4:C10) -> 20972.023 | D11: =SUM(D4:D10) -> 12884.326 | E11: =SUM(E4:E10) -> 10844.169 | F11: =SUM(F4:F10) -> 5947.1232 | G11: =SUM(G4:G10) -> 4630.2636 | H11: =SUM(H4:H10) -> 3373.7686 | I11: =SUM(I4:I10) -> 5549.8718 | J11: =SUM(J4:J10) -> 7710.3417 | K11: =SUM(K4:K10) -> 5490.0589 | L11: =SUM(C11:K11) -> 77401.945 | M11: =SUM(M4:M10) -> 2354.3382 | N11: =SUM(N4:N10) -> 4385.0233 | O11: =SUM(O4:O10) -> 4650.1261 | P11: =SUM(M11:O11) -> 11389.488 | Q11: =SUM(Q4:Q10) -> 4544.1144 | R11: =SUM(R4:R10) -> 3356.0823 | S11: =SUM(S4:S10) -> 1679.9823 | T11: =SUM(T4:T10) -> 1879.8409 | U11: =SUM(U4:U10) -> 859.80142 | V11: =SUM(V4:V10) -> 832.909 | W11: =SUM(W4:W10) -> 336.574 | X11: =SUM(Q11:W11) -> 13489.304 | Y11: =L11+P11+X11 -> 102280.74
A12: 지급수수료 | B12: 지급수수료 열원 | C12: =동탄!D13 -> 445.77269 | D12: =화성!D13 -> 374.535 | E12: =파주!D13 -> 569.415 | F12: =광교!D13 -> 237.51 | G12: =판교!D13 -> 217.21 | H12: =삼송!D13 -> 232.435 | I12: =양산!D13 -> 677.005 | J12: =대구!D13 -> 428.33 | K12: =청주!D13 -> 445.585 | L12: =SUM(C12:K12) -> 3627.7977 | M12: =수원!D13 -> 106.575 | N12: =광주전남!D13 -> 788.655 | O12: =강남!D13 -> 240.555 | P12: =SUM(M12:O12) -> 1135.785 | Q12: =중앙!D13 -> 241.57 | R12: =고양!D13 -> 101.5 | S12: =용인!D13 -> 193.865 | T12: =분당!D13 -> 65.975 | U12: =세종!D13 -> 79.17 | V12: =김해!D13 -> 162.4 | W12: =평택!D13 -> 51.765 | X12: =SUM(Q12:W12) -> 896.245 | Y12: =L12+P12+X12 -> 5659.8277
A13: 손익예산 합계 | C13: =C12+C11 -> 21417.795 | D13: =D12+D11 -> 13258.861 | E13: =E12+E11 -> 11413.584 | F13: =F12+F11 -> 6184.6332 | G13: =G12+G11 -> 4847.4736 | H13: =H12+H11 -> 3606.2036 | I13: =I12+I11 -> 6226.8768 | J13: =J12+J11 -> 8138.6717 | K13: =K12+K11 -> 5935.6439 | L13: =SUM(C13:K13) -> 81029.743 | M13: =M12+M11 -> 2460.9132 | N13: =N12+N11 -> 5173.6783 | O13: =O12+O11 -> 4890.6811 | P13: =SUM(M13:O13) -> 12525.273 | Q13: =Q12+Q11 -> 4785.6844 | R13: =R12+R11 -> 3457.5823 | S13: =S12+S11 -> 1873.8473 | T13: =T12+T11 -> 1945.8159 | U13: =U12+U11 -> 938.97142 | V13: =V12+V11 -> 995.309 | W13: =W12+W11 -> 388.339 | X13: =SUM(Q13:W13) -> 14385.549 | Y13: =L13+P13+X13 -> 107940.56
A14: 건물 | C14: =동탄!D15 -> 19 | D14: =화성!D15 -> 0 | E14: =파주!D15 -> 0 | F14: =광교!D15 -> 28 | G14: =판교!D15 -> 6 | H14: =삼송!D15 -> 0 | I14: =양산!D15 -> 11 | J14: =대구!D15 -> 0 | K14: =청주!D15 -> 0 | L14: =SUM(C14:K14) -> 64 | M14: =수원!D15 -> 0 | N14: =광주전남!D15 -> 0 | O14: =강남!D15 -> 0 | P14: =SUM(M14:O14) -> 0 | Q14: =중앙!D15 -> 0 | R14: =고양!D15 -> 0 | S14: =용인!D15 -> 0 | T14: =분당!D15 -> 0 | U14: =세종!D15 -> 0 | V14: =김해!D15 -> 0 | W14: =평택!D15 -> 0 | X14: =SUM(Q14:W14) -> 0 | Y14: =L14+P14+X14 -> 64
A15: 구축물 | C15: =동탄!D16 -> 0 | D15: =화성!D16 -> 15 | E15: =파주!D16 -> 0 | F15: =광교!D16 -> 0 | G15: =판교!D16 -> 0 | H15: =삼송!D16 -> 0 | I15: =양산!D16 -> 0 | J15: =대구!D16 -> 0 | K15: =청주!D16 -> 0 | L15: =SUM(C15:K15) -> 15 | M15: =수원!D16 -> 0 | N15: =광주전남!D16 -> 0 | O15: =강남!D16 -> 0 | P15: =SUM(M15:O15) -> 0 | Q15: =중앙!D16 -> 0 | R15: =고양!D16 -> 0 | S15: =용인!D16 -> 0 | T15: =분당!D16 -> 0 | U15: =세종!D16 -> 0 | V15: =김해!D16 -> 0 | W15: =평택!D16 -> 0 | X15: =SUM(Q15:W15) -> 0 | Y15: =L15+P15+X15 -> 15
A16: 기계장치 | B16: 고온부품재생+LTSA | C16: =동탄!D17 -> 0 | D16: =화성!D17 -> 3000 | E16: =파주!D17 -> 2344 | F16: =광교!D17 -> 63 | G16: =판교!D17 -> 0 | H16: =삼송!D17 -> 713 | I16: =양산!D17 -> 0 | J16: =대구!D17 -> 0 | K16: =청주!D17 -> 0 | L16: =SUM(C16:K16) -> 6120 | M16: =수원!D17 -> 0 | N16: =광주전남!D17 -> 0 | O16: =강남!D17 -> 0 | P16: =SUM(M16:O16) -> 0 | Q16: =중앙!D17 -> 0 | R16: =고양!D17 -> 0 | S16: =용인!D17 -> 0 | T16: =분당!D17 -> 0 | U16: =세종!D17 -> 0 | V16: =김해!D17 -> 0 | W16: =평택!D17 -> 0 | X16: =SUM(Q16:W16) -> 0 | Y16: =L16+P16+X16 -> 6120
B17: 기타기계장치 | C17: =동탄!D18 -> 328.03298 | D17: =화성!D18 -> 2074.0999 | E17: =파주!D18 -> 2092.1431 | F17: =광교!D18 -> 725.97267 | G17: =판교!D18 -> 2112 | H17: =삼송!D18 -> 844.86944 | I17: =양산!D18 -> 913.80957 | J17: =대구!D18 -> 2500 | K17: =청주!D18 -> 706 | L17: =SUM(C17:K17) -> 12296.928 | M17: =수원!D18 -> 356.58101 | N17: =광주전남!D18 -> 1522.6725 | O17: =강남!D18 -> 1371.265 | P17: =SUM(M17:O17) -> 3250.5186 | Q17: =중앙!D18 -> 941.62565 | R17: =고양!D18 -> 1168.2751 | S17: =용인!D18 -> 571.77487 | T17: =분당!D18 -> 950.89767 | U17: =세종!D18 -> 77.266875 | V17: =김해!D18 -> 81.387775 | W17: =평택!D18 -> 9.272025 | X17: =SUM(Q17:W17) -> 3800.5 | Y17: =L17+P17+X17 -> 19347.946
B18: 계 | C18: =SUM(C16:C17) -> 328.03298 | D18: =SUM(D16:D17) -> 5074.0999 | E18: =SUM(E16:E17) -> 4436.1431 | F18: =SUM(F16:F17) -> 788.97267 | G18: =SUM(G16:G17) -> 2112 | H18: =SUM(H16:H17) -> 1557.8694 | I18: =SUM(I16:I17) -> 913.80957 | J18: =SUM(J16:J17) -> 2500 | K18: =SUM(K16:K17) -> 706 | L18: =SUM(C18:K18) -> 18416.928 | M18: =SUM(M16:M17) -> 356.58101 | N18: =SUM(N16:N17) -> 1522.6725 | O18: =SUM(O16:O17) -> 1371.265 | P18: =SUM(M18:O18) -> 3250.5186 | Q18: =SUM(Q16:Q17) -> 941.62565 | R18: =SUM(R16:R17) -> 1168.2751 | S18: =SUM(S16:S17) -> 571.77487 | T18: =SUM(T16:T17) -> 950.89767 | U18: =SUM(U16:U17) -> 77.266875 | V18: =SUM(V16:V17) -> 81.387775 | W18: =SUM(W16:W17) -> 9.272025 | X18: =SUM(Q18:W18) -> 3800.5 | Y18: =L18+P18+X18 -> 25467.946
A19: 건가-외주비 | B19: MI 및 A급 정비 | C19: =동탄!D19 -> 0 | D19: =화성!D19 -> 0 | E19: =파주!D19 -> 0 | F19: =광교!D19 -> 0 | G19: =판교!D19 -> 0 | H19: =삼송!D19 -> 0 | I19: =양산!D19 -> 0 | J19: =대구!D19 -> 0 | K19: =청주!D19 -> 0 | L19: =SUM(C19:K19) -> 0 | M19: =수원!D19 -> 0 | N19: =광주전남!D19 -> 0 | O19: =강남!D19 -> 0 | P19: =SUM(M19:O19) -> 0 | Q19: =중앙!D19 -> 0 | R19: =고양!D19 -> 0 | S19: =용인!D19 -> 0 | T19: =분당!D19 -> 0 | U19: =세종!D19 -> 0 | V19: =김해!D19 -> 0 | W19: =평택!D19 -> 0 | X19: =SUM(Q19:W19) -> 0 | Y19: =L19+P19+X19 -> 0
A20: 공구와기구 | C20: =동탄!D20 -> 56.602091 | D20: =화성!D20 -> 76 | E20: =파주!D20 -> 419.195 | F20: =광교!D20 -> 11.850124 | G20: =판교!D20 -> 34.473088 | H20: =삼송!D20 -> 19 | I20: =양산!D20 -> 28.725561 | J20: =대구!D20 -> 102 | K20: =청주!D20 -> 62.520339 | L20: =SUM(C20:K20) -> 810.3662 | M20: =수원!D20 -> 0 | N20: =광주전남!D20 -> 75.40988 | O20: =강남!D20 -> 30 | P20: =SUM(M20:O20) -> 105.40988 | Q20: =중앙!D20 -> 0 | R20: =고양!D20 -> 21 | S20: =용인!D20 -> 0 | T20: =분당!D20 -> 0 | U20: =세종!D20 -> 0 | V20: =김해!D20 -> 0 | W20: =평택!D20 -> 0 | X20: =SUM(Q20:W20) -> 21 | Y20: =L20+P20+X20 -> 936.77608
A21: 예비품 | B21: 재생고온부품 | C21: =동탄!D21 -> 0 | D21: =화성!D21 -> 8166 | E21: =파주!D21 -> 0 | F21: =광교!D21 -> 8182 | G21: =판교!D21 -> 591 | H21: =삼송!D21 -> 0 | I21: =양산!D21 -> 0 | J21: =대구!D21 -> 0 | K21: =청주!D21 -> 0 | L21: =SUM(C21:K21) -> 16939 | M21: =수원!D21 -> 0 | N21: =광주전남!D21 -> 0 | O21: =강남!D21 -> 0 | P21: =SUM(M21:O21) -> 0 | Q21: =중앙!D21 -> 0 | R21: =고양!D21 -> 0 | S21: =용인!D21 -> 0 | T21: =분당!D21 -> 0 | U21: =세종!D21 -> 0 | V21: =김해!D21 -> 0 | W21: =평택!D21 -> 0 | X21: =SUM(Q21:W21) -> 0 | Y21: =L21+P21+X21 -> 16939
B22: 자산화예비품 | C22: =동탄!D22 -> 363 | D22: =화성!D22 -> 1052.8726 | E22: =파주!D22 -> 18 | F22: =광교!D22 -> 157.59798 | G22: =판교!D22 -> 180 | H22: =삼송!D22 -> 100 | I22: =양산!D22 -> 145.43334 | J22: =대구!D22 -> 369 | K22: =청주!D22 -> 358.22464 | L22: =SUM(C22:K22) -> 2744.1286 | M22: =수원!D22 -> 0 | N22: =광주전남!D22 -> 386 | O22: =강남!D22 -> 107 | P22: =SUM(M22:O22) -> 493 | Q22: =중앙!D22 -> 29 | R22: =고양!D22 -> 0 | S22: =용인!D22 -> 0 | T22: =분당!D22 -> 0 | U22: =세종!D22 -> 0 | V22: =김해!D22 -> 0 | W22: =평택!D22 -> 0 | X22: =SUM(Q22:W22) -> 29 | Y22: =L22+P22+X22 -> 3266.1286
B23: 저장품 | C23: =동탄!D23 -> 2 | D23: =화성!D23 -> 107 | E23: =파주!D23 -> 126 | F23: =광교!D23 -> 13 | G23: =판교!D23 -> 54 | H23: =삼송!D23 -> 104 | I23: =양산!D23 -> 91 | J23: =대구!D23 -> 6 | K23: =청주!D23 -> 84 | L23: =SUM(C23:K23) -> 587 | M23: =수원!D23 -> 0 | N23: =광주전남!D23 -> 84 | O23: =강남!D23 -> 43.09136 | P23: =SUM(M23:O23) -> 127.09136 | Q23: =중앙!D23 -> 0 | R23: =고양!D23 -> 10 | S23: =용인!D23 -> 0 | T23: =분당!D23 -> 0 | U23: =세종!D23 -> 0 | V23: =김해!D23 -> 0 | W23: =평택!D23 -> 0 | X23: =SUM(Q23:W23) -> 10 | Y23: =L23+P23+X23 -> 724.09136
B24: 계 | C24: =SUM(C21:C23) -> 365 | D24: =SUM(D21:D23) -> 9325.8726 | E24: =SUM(E21:E23) -> 144 | F24: =SUM(F21:F23) -> 8352.598 | G24: =SUM(G21:G23) -> 825 | H24: =SUM(H21:H23) -> 204 | I24: =SUM(I21:I23) -> 236.43334 | J24: =SUM(J21:J23) -> 375 | K24: =SUM(K21:K23) -> 442.22464 | L24: =SUM(C24:K24) -> 20270.129 | M24: =SUM(M21:M23) -> 0 | N24: =SUM(N21:N23) -> 470 | O24: =SUM(O21:O23) -> 150.09136 | P24: =SUM(M24:O24) -> 620.09136 | Q24: =SUM(Q21:Q23) -> 29 | R24: =SUM(R21:R23) -> 10 | S24: =SUM(S21:S23) -> 0 | T24: =SUM(T21:T23) -> 0 | U24: =SUM(U21:U23) -> 0 | V24: =SUM(V21:V23) -> 0 | W24: =SUM(W21:W23) -> 0 | X24: =SUM(Q24:W24) -> 39 | Y24: =L24+P24+X24 -> 20929.22
A25: 자본예산 합계 | C25: =C14+C15+C19+C18+C20+C24 -> 768.63507 | D25: =D14+D15+D19+D18+D20+D24 -> 14490.973 | E25: =E14+E15+E19+E18+E20+E24 -> 4999.3381 | F25: =F14+F15+F19+F18+F20+F24 -> 9181.4208 | G25: =G14+G15+G19+G18+G20+G24 -> 2977.4731 | H25: =H14+H15+H19+H18+H20+H24 -> 1780.8694 | I25: =I14+I15+I19+I18+I20+I24 -> 1189.9685 | J25: =J14+J15+J19+J18+J20+J24 -> 2977 | ... Y25: =Y14+Y15+Y19+Y18+Y20+Y24 -> 47412.942
A26: 투자비 | B26: 열원공사비 등 | C26: =동탄!D25 -> 1173.0355 | D26: =화성!D25 -> 343.1715 | E26: =파주!D25 -> 20000 | F26: =광교!D25 -> 140.07 | G26: =판교!D25 -> 1418.97 | H26: =삼송!D25 -> 719.635 | I26: =양산!D25 -> 2.03 | J26: =대구!D25 -> 648.585 | K26: =청주!D25 -> 3011.505 | L26: =SUM(C26:K26) -> 27457.002 | M26: =수원!D25 -> 43.645 | N26: =광주전남!D25 -> 538.965 | O26: =강남!D25 -> 7000 | P26: =SUM(M26:O26) -> 7582.61 | Q26: =중앙!D25 -> 1058 | R26: =고양!D25 -> 702 | S26: =용인!D25 -> 547 | T26: =분당!D25 -> 0 | U26: =세종!D25 -> 0 | V26: =김해!D25 -> 262 | W26: =평택!D25 -> 0 | X26: =SUM(Q26:W26) -> 2569 | Y26: =L26+P26+X26 -> 37608.612
B31: 건물/구축물 | C31: =INT(C4*0.8)-200 -> 572 | D31: =INT(D4*0.8) -> 298 | E31: =INT(E4*0.8)-300 -> 343 | F31: =INT(F4*0.8) -> 35 | G31: =INT(G4*0.8) -> 248 | H31: =INT(H4*0.8)-50 -> 183 | I31: =INT(I4*0.8) -> 132 | J31: =INT(J4*0.8) -> 2 | K31: =INT(K4*0.8) -> 24 | M31: =INT(M4*0.8) -> 181 | N31: =INT(N4*0.8) -> 194 | O31: =INT(O4*0.8) -> 130 | Q31: =INT(Q4*0.8) -> 168 | R31: =INT(R4*0.8) -> 86 | S31: =INT(S4*0.8) -> 69 | T31: =INT(T4*0.8) -> 32 | U31: =INT(U4*0.8) -> 25 | V31: =INT(V4*0.8) -> 121 | W31: =INT(W4*0.8) -> 0 | Y31: =SUM(C31:X31) -> 2843
B32: 열원정기점검 | C32: =INT(C5*0.95) -> 3187 | D32: =INT(D5*0.95) -> 3703 | E32: =INT(E5*0.95) -> 2012 | F32: =INT(F5*0.95) -> 917 | G32: =INT(G5*0.95) -> 821 | H32: =INT(H5*0.95) -> 608 | I32: =INT(I5*0.95) -> 1646 | J32: =INT(J5*0.95) -> 2381 | K32: =INT(K5*0.95) -> 1053 | M32: =INT(M5*0.95) -> 840 | N32: =INT(N5*0.95) -> 1169 | O32: =INT(O5*0.95) -> 1763 | Q32: =INT(Q5*0.95) -> 1295 | R32: =INT(R5*0.95) -> 612 | S32: =INT(S5*0.95) -> 455 | T32: =INT(T5*0.95) -> 589 | U32: =INT(U5*0.95) -> 109 | V32: =INT(V5*0.95) -> 296 | W32: =INT(W5*0.95) -> 159 | Y32: =SUM(C32:X32) -> 23615
B33: 열원경상정비 | C33: =C6 -> 8215.0141 | D33: =D6 -> 6346.186 | E33: =E6 -> 5931.0053 | F33: =F6 -> 2437.5123 | G33: =G6 -> 2530.2326 | H33: =H6 -> 1825.5587 | I33: =I6 -> 2274.7368 | J33: =J6 -> 3763.4119 | K33: =K6 -> 3419.3168 | M33: =M6 -> 724.24817 | N33: =N6 -> 1800.8333 | O33: =O6 -> 1264.0861 | Q33: =Q6 -> 1096.1594 | R33: =R6 -> 720.12727 | S33: =S6 -> 697.46232 | T33: =T6 -> 622.2559 | U33: =U6 -> 281.25142 | V33: =V6 -> 41.209 | W33: =W6 -> 41.209 | Y33: =Y6 -> 44031.816
B34: 열원정기유지보수 | C34: =C7 -> 5254.0748 | D34: =D7 -> 377.58 | E34: =E7 -> 656.705 | F34: =F7 -> 990.82 | G34: =G7 -> 190.82 | H34: =H7 -> 161.385 | I34: =I7 -> 236.495 | J34: =J7 -> 269.99 | K34: =K7 -> 206.045 | M34: =M7 -> 152.25 | N34: =N7 -> 211.12 | O34: =O7 -> 595.805 | Q34: =Q7 -> 697.305 | R34: =R7 -> 546.07 | S34: =S7 -> 120.785 | T34: =T7 -> 85.26 | U34: =U7 -> 61.915 | V34: =V7 -> 53.795 | W34: =W7 -> 94.395 | Y34: =SUM(C34:X34) -> 10962.615
B35: 열원보완및개선 | C35: =INT(C8*0.8) -> 1874 | D35: =INT(D8*0.8) -> 993 | E35: =INT(E8*0.8) -> 583 | F35: =INT(F8*0.8) -> 1008 | G35: =INT(G8*0.8) -> 380 | H35: =INT(H8*0.8) -> 318 | I35: =INT(I8*0.8) -> 726 | J35: =INT(J8*0.8) -> 626 | K35: =INT(K8*0.8) -> 302 | M35: =INT(M8*0.8) -> 235 | N35: =INT(N8*0.8) -> 578 | O35: =INT(O8*0.8) -> 517 | Q35: =INT(Q8*0.8) -> 854 | R35: =INT(R8*0.8) -> 1013 | S35: =INT(S8*0.8) -> 181 | T35: =INT(T8*0.8) -> 360 | U35: =INT(U8*0.8) -> 272 | V35: =INT(V8*0.8) -> 214 | W35: =INT(W8*0.8) -> 22 | Y35: =SUM(C35:X35) -> 11056
B36: 비저장품(보수자재) | C36: =C9 -> 754.145 | D36: =D9 -> 582.61 | E36: =E9 -> 544.04 | F36: =F9 -> 223.3 | G36: =G9 -> 232.435 | H36: =H9 -> 50.75 | I36: =I9 -> 208.075 | J36: =J9 -> 345.1 | K36: =K9 -> 313.635 | M36: =M9 -> 63.945 | N36: =N9 -> 159.355 | O36: =O9 -> 111.65 | Q36: =Q9 -> 97.44 | R36: =R9 -> 63.945 | S36: =S9 -> 61.915 | T36: =T9 -> 54.81 | U36: =U9 -> 25.375 | V36: =V9 -> 4.06 | W36: =W9 -> 4.06 | Y36: =SUM(C36:X36) -> 3900.645
B37: 소모품(자재공기구) | C37: =C10 -> 84.245 | D37: =D10 -> 64.96 | E37: =E10 -> 60.9 | F37: =F10 -> 24.36 | G37: =G10 -> 25.375 | H37: =H10 -> 6.09 | I37: =I10 -> 23.345 | J37: =J10 -> 38.57 | K37: =K10 -> 34.51 | M37: =M10 -> 7.105 | N37: =N10 -> 17.255 | O37: =O10 -> 12.18 | Q37: =Q10 -> 11.165 | R37: =R10 -> 7.105 | S37: =S10 -> 7.105 | T37: =T10 -> 6.09 | U37: =U10 -> 3.045 | V37: =V10 -> 1.015 | W37: =W10 -> 1.015 | Y37: =SUM(C37:X37) -> 435.435
B39: 지급수수료 열원 | C39: =INT(C12*0.9) -> 401 | D39: =INT(D12*0.9) -> 337 | E39: =INT(E12*0.9) -> 512 | F39: =INT(F12*0.9) -> 213 | G39: =INT(G12*0.9) -> 195 | H39: =INT(H12*0.9) -> 209 | I39: =INT(I12*0.9) -> 609 | J39: =INT(J12*0.9) -> 385 | K39: =INT(K12*0.9) -> 401 | M39: =INT(M12*0.9) -> 95 | N39: =INT(N12*0.9) -> 709 | O39: =INT(O12*0.9) -> 216 | Q39: =INT(Q12*0.9) -> 217 | R39: =INT(R12*0.9) -> 91 | S39: =INT(S12*0.9) -> 174 | T39: =INT(T12*0.9) -> 59 | U39: =INT(U12*0.9) -> 71 | V39: =INT(V12*0.9) -> 146 | W39: =INT(W12*0.9) -> 46 | Y39: =SUM(C39:X39) -> 5086
Y40: =SUM(Y31:Y39) -> 101930.51 | Z40: =Y13-Y40 -> 6010.0536
C41: =C14 -> 19 | D41: =D14 -> 0 | E41: =E14 -> 0 | F41: =F14 -> 28 | G41: =G14 -> 6 | H41: =H14 -> 0 | I41: =I14 -> 11 | J41: =J14 -> 0 | K41: =K14 -> 0 | M41: =M14 -> 0 | N41: =N14 -> 0 | O41: =O14 -> 0 | Q41: =Q14 -> 0 | R41: =R14 -> 0 | S41: =S14 -> 0 | T41: =T14 -> 0 | U41: =U14 -> 0 | V41: =V14 -> 0 | W41: =W14 -> 0
C42: =C15 -> 0 | D42: =D15 -> 15 | E42: =E15 -> 0 | F42: =F15 -> 0 | G42: =G15 -> 0 | H42: =H15 -> 0 | I42: =I15 -> 0 | J42: =J15 -> 0 | K42: =K15 -> 0 | M42: =M15 -> 0 | N42: =N15 -> 0 | O42: =O15 -> 0 | Q42: =Q15 -> 0 | R42: =R15 -> 0 | S42: =S15 -> 0 | T42: =T15 -> 0 | U42: =U15 -> 0 | V42: =V15 -> 0 | W42: =W15 -> 0
C43: =C16 -> 0 | D43: =D16 -> 3000 | E43: =E16 -> 2344 | F43: =F16 -> 63 | G43: =G16 -> 0 | H43: =H16 -> 713 | I43: =I16 -> 0 | J43: =J16 -> 0 | K43: =K16 -> 0 | M43: =M16 -> 0 | N43: =N16 -> 0 | O43: =O16 -> 0 | Q43: =Q16 -> 0 | R43: =R16 -> 0 | S43: =S16 -> 0 | T43: =T16 -> 0 | U43: =U16 -> 0 | V43: =V16 -> 0 | W43: =W16 -> 0
C44: =C17 -> 328.03298 | D44: =D17 -> 2074.0999 | E44: =E17 -> 2092.1431 | F44: =F17 -> 725.97267 | G44: =G17 -> 2112 | H44: =H17 -> 844.86944 | I44: =I17 -> 913.80957 | J44: =J17 -> 2500 | K44: =K17 -> 706 | M44: =M17 -> 356.58101 | N44: =N17 -> 1522.6725 | O44: =O17 -> 1371.265 | Q44: =Q17 -> 941.62565 | R44: =R17 -> 1168.2751 | S44: =S17 -> 571.77487 | T44: =T17 -> 950.89767 | U44: =U17 -> 77.266875 | V44: =V17 -> 81.387775 | W44: =W17 -> 9.272025
C45: =C18 -> 328.03298 | D45: =D18 -> 5074.0999 | E45: =E18 -> 4436.1431 | F45: =F18 -> 788.97267 | G45: =G18 -> 2112 | H45: =H18 -> 1557.8694 | I45: =I18 -> 913.80957 | J45: =J18 -> 2500 | K45: =K18 -> 706 | M45: =M18 -> 356.58101 | N45: =N18 -> 1522.6725 | O45: =O18 -> 1371.265 | Q45: =Q18 -> 941.62565 | R45: =R18 -> 1168.2751 | S45: =S18 -> 571.77487 | T45: =T18 -> 950.89767 | U45: =U18 -> 77.266875 | V45: =V18 -> 81.387775 | W45: =W18 -> 9.272025
C46: =C19 -> 0 | D46: =D19 -> 0 | E46: =E19 -> 0 | F46: =F19 -> 0 | G46: =G19 -> 0 | H46: =H19 -> 0 | I46: =I19 -> 0 | J46: =J19 -> 0 | K46: =K19 -> 0 | M46: =M19 -> 0 | N46: =N19 -> 0 | O46: =O19 -> 0 | Q46: =Q19 -> 0 | R46: =R19 -> 0 | S46: =S19 -> 0 | T46: =T19 -> 0 | U46: =U19 -> 0 | V46: =V19 -> 0 | W46: =W19 -> 0
...

Sheet 28년
Y2: [단위 : 백만원]
A3: 2028년 | C3: 동탄 | D3: 화성 | E3: 파주 | F3: 광교 | G3: 판교 | H3: 삼송 | I3: 양산 | J3: 대구 | K3: 청주 | L3: 소계 | M3: 수원 | N3: 광주전남 | O3: 강남 | P3: 소계 | Q3: 중앙 | R3: 고양 | S3: 용인 | T3: 분당 | U3: 세종 | V3: 김해 | W3: 평택 | X3: 소계 | Y3: 합계
A4: 수선유지비 | B4: 건물/구축물 | C4: =동탄!E6 -> 979.74397 | D4: =화성!E6 -> 378.09257 | E4: =파주!E6 -> 815.9382 | F4: =광교!E6 -> 45.3299 | G4: =판교!E6 -> 315.24885 | H4: =삼송!E6 -> 295.67457 | I4: =양산!E6 -> 167.92667 | J4: =대구!E6 -> 3.090675 | K4: =청주!E6 -> 30.90675 | L4: =SUM(C4:K4) -> 3031.9522 | M4: =수원!E6 -> 230.7704 | N4: =광주전남!E6 -> 246.22377 | O4: =강남!E6 -> 165.86622 | P4: =SUM(M4:O4) -> 642.8604 | Q4: =중앙!E6 -> 213.25657 | R4: =고양!E6 -> 109.20385 | S4: =용인!E6 -> 88.59935 | T4: =분당!E6 -> 41.209 | U4: =세종!E6 -> 32.9672 | V4: =김해!E6 -> 154.53375 | W4: =평택!E6 -> 0 | X4: =SUM(Q4:W4) -> 639.76972 | Y4: =L4+P4+X4 -> 4314.5823
B5: 열원정기점검 | C5: =동탄!E7 -> 7292.4852 | D5: =화성!E7 -> 1362.4303 | E5: =파주!E7 -> 4142.5347 | F5: =광교!E7 -> 1775.5619 | G5: =판교!E7 -> 877.74766 | H5: =삼송!E7 -> 650.41195 | I5: =양산!E7 -> 835.51247 | J5: =대구!E7 -> 1125.1499 | K5: =청주!E7 -> 2544.2445 | L5: =SUM(C5:K5) -> 20606.079 | M5: =수원!E7 -> 898.3562 | N5: =광주전남!E7 -> 1249.6629 | O5: =강남!E7 -> 1884.2815 | P5: =SUM(M5:O5) -> 4032.3006 | Q5: =중앙!E7 -> 1384.6224 | R5: =고양!E7 -> 654.19287 | S5: =용인!E7 -> 486.2662 | T5: =분당!E7 -> 629.46747 | U5: =세종!E7 -> 117.44565 | V5: =김해!E7 -> 317.3093 | W5: =평택!E7 -> 169.98712 | X5: =SUM(Q5:W5) -> 3759.291 | Y5: =L5+P5+X5 -> 28397.67
B6: 열원경상정비 | C6: =동탄!E8 -> 8338.2394 | D6: =화성!E8 -> 6441.3788 | E6: =파주!E8 -> 6019.9704 | F6: =광교!E8 -> 2474.075 | G6: =판교!E8 -> 2568.1861 | H6: =삼송!E8 -> 1852.9421 | I6: =양산!E8 -> 2308.8579 | J6: =대구!E8 -> 3819.8631 | K6: =청주!E8 -> 3470.6065 | L6: =SUM(C6:K6) -> 37294.119 | M6: =수원!E8 -> 2568.1861 | N6: =광주전남!E8 -> 1827.8458 | O6: =강남!E8 -> 1283.0474 | P6: =SUM(M6:O6) -> 5679.0793 | Q6: =중앙!E8 -> 1112.6018 | R6: =고양!E8 -> 730.92918 | S6: =용인!E8 -> 707.92426 | T6: =분당!E8 -> 631.58974 | U6: =세종!E8 -> 285.4702 | V6: =김해!E8 -> 41.827135 | W6: =평택!E8 -> 41.827135 | X6: =SUM(Q6:W6) -> 3552.1694 | Y6: =L6+P6+X6 -> 46525.368
B7: 열원정기유지보수 | C7: =동탄!E9 -> 5330.6809 | D7: =화성!E9 -> 383.2437 | E7: =파주!E9 -> 666.55557 | F7: =광교!E9 -> 993.6823 | G7: =판교!E9 -> 193.6823 | H7: =삼송!E9 -> 163.80577 | I7: =양산!E9 -> 240.04242 | J7: =대구!E9 -> 274.03985 | K7: =청주!E9 -> 209.13567 | L7: =SUM(C7:K7) -> 8454.8685 | M7: =수원!E9 -> 154.53375 | N7: =광주전남!E9 -> 214.2868 | O7: =강남!E9 -> 604.74207 | P7: =SUM(M7:O7) -> 973.56262 | Q7: =중앙!E9 -> 707.76457 | R7: =고양!E9 -> 554.26105 | S7: =용인!E9 -> 122.59677 | T7: =분당!E9 -> 86.5389 | U7: =세종!E9 -> 62.843725 | V7: =김해!E9 -> 54.601925 | W7: =평택!E9 -> 95.810925 | X7: =SUM(Q7:W7) -> 1684.4179 | Y7: =L7+P7+X7 -> 11112.849
B8: 열원보완및개선 | C8: =동탄!E10 -> 2524.3569 | D8: =화성!E10 -> 876.68629 | E8: =파주!E10 -> 1498.9774 | F8: =광교!E10 -> 1279.5394 | G8: =판교!E10 -> 483.17552 | H8: =삼송!E10 -> 403.8482 | I8: =양산!E10 -> 922.05137 | J8: =대구!E10 -> 795.3337 | K8: =청주!E10 -> 383.2437 | L8: =SUM(C8:K8) -> 9167.2125 | M8: =수원!E10 -> 298.76525 | N8: =광주전남!E10 -> 733.5202 | O8: =강남!E10 -> 656.25332 | P8: =SUM(M8:O8) -> 1688.5388 | Q8: =중앙!E10 -> 1083.7967 | R8: =고양!E10 -> 1285.7208 | S8: =용인!E10 -> 229.74017 | T8: =분당!E10 -> 457.4199 | U8: =세종!E10 -> 345.12537 | V8: =김해!E10 -> 271.9794 | W8: =평택!E10 -> 28.8463 | X8: =SUM(Q8:W8) -> 3702.6286 | Y8: =L8+P8+X8 -> 14558.38
B9: 비저장품(보수자재) | C9: =동탄!E11 -> 776.93903 | D9: =화성!E11 -> 600.21939 | E9: =파주!E11 -> 560.48361 | F9: =광교!E11 -> 230.04924 | G9: =판교!E11 -> 239.46035 | H9: =삼송!E11 -> 52.283919 | I9: =양산!E11 -> 214.36407 | J9: =대구!E11 -> 355.53065 | K9: =청주!E11 -> 323.11462 | L9: =SUM(C9:K9) -> 3352.4449 | M9: =수원!E11 -> 65.877738 | N9: =광주전남!E11 -> 164.1715 | O9: =강남!E11 -> 115.02462 | P9: =SUM(M9:O9) -> 345.07386 | Q9: =중앙!E11 -> 100.38512 | R9: =고양!E11 -> 65.877738 | S9: =용인!E11 -> 63.786381 | T9: =분당!E11 -> 56.466632 | U9: =세종!E11 -> 26.141959 | V9: =김해!E11 -> 4.1827135 | W9: =평택!E11 -> 4.1827135 | X9: =SUM(Q9:W9) -> 321.02326 | Y9: =L9+P9+X9 -> 4018.542
B10: 소모품(자재공기구) | C10: =동탄!E12 -> 86.791305 | D10: =화성!E12 -> 66.923416 | E10: =파주!E12 -> 62.740702 | F10: =광교!E12 -> 25.096281 | G10: =판교!E12 -> 26.141959 | H10: =삼송!E12 -> 6.2740702 | I10: =양산!E12 -> 24.050603 | J10: =대구!E12 -> 39.735778 | K10: =청주!E12 -> 35.553065 | L10: =SUM(C10:K10) -> 373.30718 | M10: =수원!E12 -> 7.3197486 | N10: =광주전남!E12 -> 17.776532 | O10: =강남!E12 -> 12.54814 | P10: =SUM(M10:O10) -> 37.644421 | Q10: =중앙!E12 -> 11.502462 | R10: =고양!E12 -> 7.3197486 | S10: =용인!E12 -> 7.3197486 | T10: =분당!E12 -> 6.2740702 | U10: =세종!E12 -> 3.1370351 | V10: =김해!E12 -> 1.0456784 | W10: =평택!E12 -> 1.0456784 | X10: =SUM(Q10:W10) -> 37.644421 | Y10: =L10+P10+X10 -> 448.59602
B11: 계 | C11: =SUM(C4:C10) -> 25329.237 | D11: =SUM(D4:D10) -> 10108.974 | E11: =SUM(E4:E10) -> 13767.201 | F11: =SUM(F4:F10) -> 6823.3341 | G11: =SUM(G4:G10) -> 4703.6427 | H11: =SUM(H4:H10) -> 3425.2406 | I11: =SUM(I4:I10) -> 4712.8055 | J11: =SUM(J4:J10) -> 6412.7437 | K11: =SUM(K4:K10) -> 6996.8048 | L11: =SUM(C11:K11) -> 82279.983 | M11: =SUM(M4:M10) -> 4223.8092 | N11: =SUM(N4:N10) -> 4453.4875 | O11: =SUM(O4:O10) -> 4721.7633 | P11: =SUM(M11:O11) -> 13399.06 | Q11: =SUM(Q4:Q10) -> 4613.9296 | R11: =SUM(R4:R10) -> 3407.5052 | S11: =SUM(S4:S10) -> 1706.2329 | T11: =SUM(T4:T10) -> 1908.9657 | U11: =SUM(U4:U10) -> 873.13114 | V11: =SUM(V4:V10) -> 845.4799 | W11: =SUM(W4:W10) -> 341.69988 | X11: =SUM(Q11:W11) -> 13696.944 | Y11: =L11+P11+X11 -> 109375.99
A12: 지급수수료 | B12: 지급수수료 열원 | C12: =동탄!E13 -> 452.45928 | D12: =화성!E13 -> 380.15302 | E12: =파주!E13 -> 577.95622 | F12: =광교!E13 -> 241.07265 | G12: =판교!E13 -> 220.46815 | H12: =삼송!E13 -> 235.92152 | I12: =양산!E13 -> 687.16007 | J12: =대구!E13 -> 434.75495 | K12: =청주!E13 -> 452.26877 | L12: =SUM(C12:K12) -> 3682.2147 | M12: =수원!E13 -> 108.17362 | N12: =광주전남!E13 -> 800.48482 | O12: =강남!E13 -> 244.16332 | P12: =SUM(M12:O12) -> 1152.8218 | Q12: =중앙!E13 -> 245.19355 | R12: =고양!E13 -> 103.0225 | S12: =용인!E13 -> 196.77297 | T12: =분당!E13 -> 66.964625 | U12: =세종!E13 -> 80.35755 | V12: =김해!E13 -> 164.836 | W12: =평택!E13 -> 52.541475 | X12: =SUM(Q12:W12) -> 909.68867 | Y12: =L12+P12+X12 -> 5744.7251
A13: 손익예산 합계 | C13: =C12+C11 -> 25781.696 | D13: =D12+D11 -> 10489.127 | E13: =E12+E11 -> 14345.157 | F13: =F12+F11 -> 7064.4067 | G13: =G12+G11 -> 4924.1109 | H13: =H12+H11 -> 3661.1621 | I13: =I12+I11 -> 5399.9655 | J13: =J12+J11 -> 6847.4986 | K13: =K12+K11 -> 7449.0736 | L13: =SUM(C13:K13) -> 85962.198 | M13: =M12+M11 -> 4331.9828 | N13: =N12+N11 -> 5253.9724 | O13: =O12+O11 -> 4965.9266 | P13: =SUM(M13:O13) -> 14551.882 | Q13: =Q12+Q11 -> 4859.1232 | R13: =R12+R11 -> 3510.5277 | S13: =S12+S11 -> 1903.0059 | T13: =T12+T11 -> 1975.9303 | U13: =U12+U11 -> 953.48869 | V13: =V12+V11 -> 1010.3159 | W13: =W12+W11 -> 394.24135 | X13: =SUM(Q13:W13) -> 14606.633 | Y13: =L13+P13+X13 -> 115120.71
A14: 건물 | C14: =동탄!E15 -> 0 | D14: =화성!E15 -> 22 | E14: =파주!E15 -> 0 | F14: =광교!E15 -> 28 | G14: =판교!E15 -> 6 | H14: =삼송!E15 -> 0 | I14: =양산!E15 -> 11 | J14: =대구!E15 -> 0 | K14: =청주!E15 -> 0 | L14: =SUM(C14:K14) -> 67 | M14: =수원!E15 -> 0 | N14: =광주전남!E15 -> 0 | O14: =강남!E15 -> 0 | P14: =SUM(M14:O14) -> 0 | Q14: =중앙!E15 -> 0 | R14: =고양!E15 -> 0 | S14: =용인!E15 -> 0 | T14: =분당!E15 -> 0 | U14: =세종!E15 -> 0 | V14: =김해!E15 -> 0 | W14: =평택!E15 -> 0 | X14: =SUM(Q14:W14) -> 0 | Y14: =L14+P14+X14 -> 67
A15: 구축물 | C15: =동탄!E16 -> 0 | D15: =화성!E16 -> 15 | E15: =파주!E16 -> 0 | F15: =광교!E16 -> 0 | G15: =판교!E16 -> 0 | H15: =삼송!E16 -> 0 | I15: =양산!E16 -> 0 | J15: =대구!E16 -> 0 | K15: =청주!E16 -> 0 | L15: =SUM(C15:K15) -> 15 | M15: =수원!E16 -> 0 | N15: =광주전남!E16 -> 0 | O15: =강남!E16 -> 0 | P15: =SUM(M15:O15) -> 0 | Q15: =중앙!E16 -> 0 | R15: =고양!E16 -> 0 | S15: =용인!E16 -> 0 | T15: =분당!E16 -> 0 | U15: =세종!E16 -> 0 | V15: =김해!E16 -> 0 | W15: =평택!E16 -> 0 | X15: =SUM(Q15:W15) -> 0 | Y15: =L15+P15+X15 -> 15
A16: 기계장치 | B16: 고온부품재생+LTSA | C16: =동탄!E17 -> 3711.251 | D16: =화성!E17 -> 1757 | E16: =파주!E17 -> 0 | F16: =광교!E17 -> 0 | G16: =판교!E17 -> 0 | H16: =삼송!E17 -> 0 | I16: =양산!E17 -> 4336 | J16: =대구!E17 -> 6636 | K16: =청주!E17 -> 0 | L16: =SUM(C16:K16) -> 16440.251 | M16: =수원!E17 -> 0 | N16: =광주전남!E17 -> 0 | O16: =강남!E17 -> 0 | P16: =SUM(M16:O16) -> 0 | Q16: =중앙!E17 -> 0 | R16: =고양!E17 -> 0 | S16: =용인!E17 -> 0 | T16: =분당!E17 -> 0 | U16: =세종!E17 -> 0 | V16: =김해!E17 -> 0 | W16: =평택!E17 -> 0 | X16: =SUM(Q16:W16) -> 0 | Y16: =L16+P16+X16 -> 16440.251
B17: 기타기계장치 | C17: =동탄!E18 -> 15149 | D17: =화성!E18 -> 1669.5249 | E17: =파주!E18 -> 2627.5442 | F17: =광교!E18 -> 1044.2383 | G17: =판교!E18 -> 1180.2363 | H17: =삼송!E18 -> 290.85591 | I17: =양산!E18 -> 180 | J17: =대구!E18 -> 1402.8877 | K17: =청주!E18 -> 706 | L17: =SUM(C17:K17) -> 24250.287 | M17: =수원!E18 -> 361.92972 | N17: =광주전남!E18 -> 1545.5126 | O17: =강남!E18 -> 1391.834 | P17: =SUM(M17:O17) -> 3299.2763 | Q17: =중앙!E18 -> 955.75003 | R17: =고양!E18 -> 1185.7993 | S17: =용인!E18 -> 580.3515 | T17: =분당!E18 -> 965.16114 | U17: =세종!E18 -> 78.425878 | V17: =김해!E18 -> 82.608592 | W17: =평택!E18 -> 9.4111054 | X17: =SUM(Q17:W17) -> 3857.5075 | Y17: =L17+P17+X17 -> 31407.071
B18: 계 | C18: =SUM(C16:C17) -> 18860.251 | D18: =SUM(D16:D17) -> 3426.5249 | E18: =SUM(E16:E17) -> 2627.5442 | F18: =SUM(F16:F17) -> 1044.2383 | G18: =SUM(G16:G17) -> 1180.2363 | H18: =SUM(H16:H17) -> 290.85591 | I18: =SUM(I16:I17) -> 4516 | J18: =SUM(J16:J17) -> 8038.8877 | K18: =SUM(K16:K17) -> 706 | L18: =SUM(C18:K18) -> 40690.538 | M18: =SUM(M16:M17) -> 361.92972 | N18: =SUM(N16:N17) -> 1545.5126 | O18: =SUM(O16:O17) -> 1391.834 | P18: =SUM(M18:O18) -> 3299.2763 | Q18: =SUM(Q16:Q17) -> 955.75003 | R18: =SUM(R16:R17) -> 1185.7993 | S18: =SUM(S16:S17) -> 580.3515 | T18: =SUM(T16:T17) -> 965.16114 | U18: =SUM(U16:U17) -> 78.425878 | V18: =SUM(V16:V17) -> 82.608592 | W18: =SUM(W16:W17) -> 9.4111054 | X18: =SUM(Q18:W18) -> 3857.5075 | Y18: =L18+P18+X18 -> 47847.322
A19: 건가-외주비 | B19: MI 및 A급 정비 | C19: =동탄!E19 -> 5000 | D19: =화성!E19 -> 0 | E19: =파주!E19 -> 9761.168 | F19: =광교!E19 -> 0 | G19: =판교!E19 -> 0 | H19: =삼송!E19 -> 0 | I19: =양산!E19 -> 0 | J19: =대구!E19 -> 0 | K19: =청주!E19 -> 0 | L19: =SUM(C19:K19) -> 14761.168 | M19: =수원!E19 -> 0 | N19: =광주전남!E19 -> 0 | O19: =강남!E19 -> 0 | P19: =SUM(M19:O19) -> 0 | Q19: =중앙!E19 -> 0 | R19: =고양!E19 -> 0 | S19: =용인!E19 -> 0 | T19: =분당!E19 -> 0 | U19: =세종!E19 -> 0 | V19: =김해!E19 -> 0 | W19: =평택!E19 -> 0 | X19: =SUM(Q19:W19) -> 0 | Y19: =L19+P19+X19 -> 14761.168
